Workbook

Sheet Amazon Model Unit Economics - V
K1: $7 per CFT | L1: 0.07
C2: Box 1 Dimensions (in) | J2: 84 | K2: 7 | L2: 0.18 | Q2: Product Size Tier | Z2: 0.06
A3: SKU | B3: Comments | C3: L (in) | D3: B (in) | E3: H (in) | F3: Gross wt (lbs) | G3: Ex-factory Price (INR) | H3: ## of boxes | I3: Box CFT | J3: Ex-factory cost | K3: Amazon SEND Shipping | L3: Import Duty (USD) | M3: Landed COGS | N3: Gross weight (lb) | O3: Dimensional weight (lb) | P3: Shipping weight (lb) | Q3: Shipping weight Class | R3: Longest side Class | S3: Median side Class | T3: Shortest side Class | U3: Final Product Size Tier | V3: Base Fare | W3: Incremental Fare per lb | X3: Cutoff Lb | Y3: FBA Fulfilment fees | Z3: FBA Storage fees | AA3: Landed COGS + FBA Fulfilment + FBA Warehousing | AB3: Return as % of Gross Sales | AC3: AZ Selling Fees as % of Gross Sales (15% of net + 3% return admin on returned items) | AD3: Ads as % of Gross Sales | AE3: Net Margin as % of Gross Sales | AF3: [Returns + Platform fees + Ads + Margin] as % of Gross Sales | AG3: [Landed COGS + FBA Fulfilment + FBA Warehousing] as % of Gross Sales | AH3: Theoratical Listing Price | AI3: ASP (Target selling Price) | AJ3: Current Ads as % of Gross Sales | AK3: Current Return % of Gross Sales | AL3: COGS% basis target price | AM3: Operating Margin% basis Target Selling Price | AN3: Net Margin% basis Target Selling Price | AO3: Profit + Ads % | AP3: Fullfillment fee% of Gross Sales | AQ3: ROE
A4: ET008 | B4: Universe | C4: 23 | D4: 15 | E4: 9 | F4: 33.3 | G4: 2200 | H4: 1 | I4: =C4*D4*E4/12^3 -> 1.796875 | J4: =G4/$J$2 -> 26.190476 | K4: =$K$2*I4 -> 12.578125 | L4: =J4*(1+$L$1)*$L$2 -> 5.0442857 | M4: =L4+K4+J4 -> 43.812887 | N4: =F4 -> 33.3 | O4: =roundup(C4*D4*E4/139,0) -> 23 | P4: =MAX(N4,O4) -> 33.3 | Q4: =if(P4<1,Cockpit!$H$7,if(P4<20,Cockpit!$H$8,if(P4<50,Cockpit!$H$9,if(P4<70,Cockpit!$H$10,if(P4<150,Cockpit!$H$11,Cockpit!$H$12))))) -> 3 | R4: =if(MAX(C4:E4)<15,Cockpit!$L$7,if(MAX(C4:E4)<18,Cockpit!$L$8,if(MAX(C4:E4)<59,Cockpit!$L$9,Cockpit!$L$10))) -> 3 | S4: =if(MEDIAN(C4:E4)<0.12,Cockpit!$L$7,if(MEDIAN(C4:E4)<14,Cockpit!$L$8,if(MEDIAN(C4:E4)<33,Cockpit!$L$9,Cockpit!$L$10))) -> 3 | T4: =if(MIN(C4:E4)<0.75,Cockpit!$L$7,if(MIN(C4:E4)<8,Cockpit!$L$8,if(MIN(C4:E4)<33,Cockpit!$L$9,Cockpit!$L$10))) -> 3 | U4: =MAX(Q4:T4) -> 3 | V4: =VLOOKUP($U4,Cockpit!$H$16:$M$22,3, FALSE) -> 10.65 | W4: =VLOOKUP($U4,Cockpit!$H$16:$M$22,4, FALSE) -> 0.38 | X4: =VLOOKUP($U4,Cockpit!$H$16:$M$22,5, FALSE) -> 1 | Y4: =V4+W4*(P4-X4) -> 22.924 | Z4: =$Z$2*AI4 -> 11.9994 | AA4: =M4+Y4+Z4 -> 78.736287 | AB4: 0.15 | AC4: =(1-AB4)*15% + 3%*AB4 -> 0.132 | AD4: 0.25 | AE4: 0.15 | AF4: =AB4+AC4+AD4+AE4 -> 0.682 | AG4: =1-AF4 -> 0.318 | AH4: =AA4/AG4 -> 247.59839 | AI4: 199.99 | AJ4: 0.25 | AK4: 0.15 | AL4: =M4/AI4 -> 0.21907539 | AM4: =1-AJ4-AK4-AC4-(Y4+Z4)/AI4 -> 0.29337427 | AN4: =1-AJ4-AK4-AC4-AA4/AI4 -> 0.07429888 | AO4: =AN4+AJ4 -> 0.32429888 | AP4: =Y4/AI4 -> 0.11462573 | AQ4: =AI4*AN4/M4 -> 0.33914755
A5: ET042MB(D) | B5: Universe | C5: 23 | D5: 6 | E5: 18 | F5: 14.1 | G5: 1650 | H5: 1 | I5: =C5*D5*E5/12^3 -> 1.4375 | J5: =G5/$J$2 -> 19.642857 | K5: =$K$2*I5 -> 10.0625 | L5: =J5*(1+$L$1)*$L$2 -> 3.7832143 | M5: =L5+K5+J5 -> 33.488571 | N5: =F5 -> 14.1 | O5: =roundup(C5*D5*E5/139,0) -> 18 | P5: =MAX(N5,O5) -> 18 | Q5: =if(P5<1,Cockpit!$H$7,if(P5<20,Cockpit!$H$8,if(P5<50,Cockpit!$H$9,if(P5<70,Cockpit!$H$10,if(P5<150,Cockpit!$H$11,Cockpit!$H$12))))) -> 2 | R5: =if(MAX(C5:E5)<15,Cockpit!$L$7,if(MAX(C5:E5)<18,Cockpit!$L$8,if(MAX(C5:E5)<59,Cockpit!$L$9,Cockpit!$L$10))) -> 3 | S5: =if(MEDIAN(C5:E5)<0.12,Cockpit!$L$7,if(MEDIAN(C5:E5)<14,Cockpit!$L$8,if(MEDIAN(C5:E5)<33,Cockpit!$L$9,Cockpit!$L$10))) -> 3 | T5: =if(MIN(C5:E5)<0.75,Cockpit!$L$7,if(MIN(C5:E5)<8,Cockpit!$L$8,if(MIN(C5:E5)<33,Cockpit!$L$9,Cockpit!$L$10))) -> 2 | U5: =MAX(Q5:T5) -> 3 | V5: =VLOOKUP($U5,Cockpit!$H$16:$M$22,3, FALSE) -> 10.65 | W5: =VLOOKUP($U5,Cockpit!$H$16:$M$22,4, FALSE) -> 0.38 | X5: =VLOOKUP($U5,Cockpit!$H$16:$M$22,5, FALSE) -> 1 | Y5: =V5+W5*(P5-X5) -> 17.11 | Z5: =$Z$2*AI5 -> 8.9994 | AA5: =M5+Y5+Z5 -> 59.597971 | AB5: 0.15 | AC5: =(1-AB5)*15% + 3%*AB5 -> 0.132 | AD5: 0.25 | AE5: 0.15 | AF5: =AB5+AC5+AD5+AE5 -> 0.682 | AG5: =1-AF5 -> 0.318 | AH5: =AA5/AG5 -> 187.415 | AI5: 149.99 | AJ5: 0.25 | AK5: 0.15 | AL5: =M5/AI5 -> 0.22327203 | AM5: =1-AJ5-AK5-AC5-(Y5+Z5)/AI5 -> 0.29392573 | AN5: =1-AJ5-AK5-AC5-AA5/AI5 -> 0.070653701 | AO5: =AN5+AJ5 -> 0.3206537 | AP5: =Y5/AI5 -> 0.11407427 | AQ5: =AI5*AN5/M5 -> 0.31644672
A6: ET042MW | B6: Universe | C6: 23 | D6: 6 | E6: 18 | F6: 14.1 | G6: 1650 | H6: 1 | I6: =C6*D6*E6/12^3 -> 1.4375 | J6: =G6/$J$2 -> 19.642857 | K6: =$K$2*I6 -> 10.0625 | L6: =J6*(1+$L$1)*$L$2 -> 3.7832143 | M6: =L6+K6+J6 -> 33.488571 | N6: =F6 -> 14.1 | O6: =roundup(C6*D6*E6/139,0) -> 18 | P6: =MAX(N6,O6) -> 18 | Q6: =if(P6<1,Cockpit!$H$7,if(P6<20,Cockpit!$H$8,if(P6<50,Cockpit!$H$9,if(P6<70,Cockpit!$H$10,if(P6<150,Cockpit!$H$11,Cockpit!$H$12))))) -> 2 | R6: =if(MAX(C6:E6)<15,Cockpit!$L$7,if(MAX(C6:E6)<18,Cockpit!$L$8,if(MAX(C6:E6)<59,Cockpit!$L$9,Cockpit!$L$10))) -> 3 | S6: =if(MEDIAN(C6:E6)<0.12,Cockpit!$L$7,if(MEDIAN(C6:E6)<14,Cockpit!$L$8,if(MEDIAN(C6:E6)<33,Cockpit!$L$9,Cockpit!$L$10))) -> 3 | T6: =if(MIN(C6:E6)<0.75,Cockpit!$L$7,if(MIN(C6:E6)<8,Cockpit!$L$8,if(MIN(C6:E6)<33,Cockpit!$L$9,Cockpit!$L$10))) -> 2 | U6: =MAX(Q6:T6) -> 3 | V6: =VLOOKUP($U6,Cockpit!$H$16:$M$22,3, FALSE) -> 10.65 | W6: =VLOOKUP($U6,Cockpit!$H$16:$M$22,4, FALSE) -> 0.38 | X6: =VLOOKUP($U6,Cockpit!$H$16:$M$22,5, FALSE) -> 1 | Y6: =V6+W6*(P6-X6) -> 17.11 | Z6: =$Z$2*AI6 -> 8.9994 | AA6: =M6+Y6+Z6 -> 59.597971 | AB6: 0.15 | AC6: =(1-AB6)*15% + 3%*AB6 -> 0.132 | AD6: 0.25 | AE6: 0.15 | AF6: =AB6+AC6+AD6+AE6 -> 0.682 | AG6: =1-AF6 -> 0.318 | AH6: =AA6/AG6 -> 187.415 | AI6: 149.99 | AJ6: 0.25 | AK6: 0.15 | AL6: =M6/AI6 -> 0.22327203 | AM6: =1-AJ6-AK6-AC6-(Y6+Z6)/AI6 -> 0.29392573 | AN6: =1-AJ6-AK6-AC6-AA6/AI6 -> 0.070653701 | AO6: =AN6+AJ6 -> 0.3206537 | AP6: =Y6/AI6 -> 0.11407427 | AQ6: =AI6*AN6/M6 -> 0.31644672
A7: ET003-N | B7: Universe | C7: 18 | D7: 18.5 | E7: 8 | F7: 21.6 | G7: 2700 | H7: 1 | I7: =C7*D7*E7/12^3 -> 1.5416667 | J7: =G7/$J$2 -> 32.142857 | K7: =$K$2*I7 -> 10.791667 | L7: =J7*(1+$L$1)*$L$2 -> 6.1907143 | M7: =L7+K7+J7 -> 49.125238 | N7: =F7 -> 21.6 | O7: =roundup(C7*D7*E7/139,0) -> 20 | P7: =MAX(N7,O7) -> 21.6 | Q7: =if(P7<1,Cockpit!$H$7,if(P7<20,Cockpit!$H$8,if(P7<50,Cockpit!$H$9,if(P7<70,Cockpit!$H$10,if(P7<150,Cockpit!$H$11,Cockpit!$H$12))))) -> 3 | R7: =if(MAX(C7:E7)<15,Cockpit!$L$7,if(MAX(C7:E7)<18,Cockpit!$L$8,if(MAX(C7:E7)<59,Cockpit!$L$9,Cockpit!$L$10))) -> 3 | S7: =if(MEDIAN(C7:E7)<0.12,Cockpit!$L$7,if(MEDIAN(C7:E7)<14,Cockpit!$L$8,if(MEDIAN(C7:E7)<33,Cockpit!$L$9,Cockpit!$L$10))) -> 3 | T7: =if(MIN(C7:E7)<0.75,Cockpit!$L$7,if(MIN(C7:E7)<8,Cockpit!$L$8,if(MIN(C7:E7)<33,Cockpit!$L$9,Cockpit!$L$10))) -> 3 | U7: =MAX(Q7:T7) -> 3 | V7: =VLOOKUP($U7,Cockpit!$H$16:$M$22,3, FALSE) -> 10.65 | W7: =VLOOKUP($U7,Cockpit!$H$16:$M$22,4, FALSE) -> 0.38 | X7: =VLOOKUP($U7,Cockpit!$H$16:$M$22,5, FALSE) -> 1 | Y7: =V7+W7*(P7-X7) -> 18.478 | Z7: =$Z$2*AI7 -> 11.94 | AA7: =M7+Y7+Z7 -> 79.543238 | AB7: 0.15 | AC7: =(1-AB7)*15% + 3%*AB7 -> 0.132 | AD7: 0.25 | AE7: 0.15 | AF7: =AB7+AC7+AD7+AE7 -> 0.682 | AG7: =1-AF7 -> 0.318 | AH7: =AA7/AG7 -> 250.13597 | AI7: 199 | AJ7: 0.25 | AK7: 0.15 | AL7: =M7/AI7 -> 0.24686049 | AM7: =1-AJ7-AK7-AC7-(Y7+Z7)/AI7 -> 0.31514573 | AN7: =1-AJ7-AK7-AC7-AA7/AI7 -> 0.068285236 | AO7: =AN7+AJ7 -> 0.31828524 | AP7: =Y7/AI7 -> 0.092854271 | AQ7: =AI7*AN7/M7 -> 0.27661468
A8: ET003-W | B8: Universe | C8: 18 | D8: 18.5 | E8: 8 | F8: 21.6 | G8: 2700 | H8: 1 | I8: =C8*D8*E8/12^3 -> 1.5416667 | J8: =G8/$J$2 -> 32.142857 | K8: =$K$2*I8 -> 10.791667 | L8: =J8*(1+$L$1)*$L$2 -> 6.1907143 | M8: =L8+K8+J8 -> 49.125238 | N8: =F8 -> 21.6 | O8: =roundup(C8*D8*E8/139,0) -> 20 | P8: =MAX(N8,O8) -> 21.6 | Q8: =if(P8<1,Cockpit!$H$7,if(P8<20,Cockpit!$H$8,if(P8<50,Cockpit!$H$9,if(P8<70,Cockpit!$H$10,if(P8<150,Cockpit!$H$11,Cockpit!$H$12))))) -> 3 | R8: =if(MAX(C8:E8)<15,Cockpit!$L$7,if(MAX(C8:E8)<18,Cockpit!$L$8,if(MAX(C8:E8)<59,Cockpit!$L$9,Cockpit!$L$10))) -> 3 | S8: =if(MEDIAN(C8:E8)<0.12,Cockpit!$L$7,if(MEDIAN(C8:E8)<14,Cockpit!$L$8,if(MEDIAN(C8:E8)<33,Cockpit!$L$9,Cockpit!$L$10))) -> 3 | T8: =if(MIN(C8:E8)<0.75,Cockpit!$L$7,if(MIN(C8:E8)<8,Cockpit!$L$8,if(MIN(C8:E8)<33,Cockpit!$L$9,Cockpit!$L$10))) -> 3 | U8: =MAX(Q8:T8) -> 3 | V8: =VLOOKUP($U8,Cockpit!$H$16:$M$22,3, FALSE) -> 10.65 | W8: =VLOOKUP($U8,Cockpit!$H$16:$M$22,4, FALSE) -> 0.38 | X8: =VLOOKUP($U8,Cockpit!$H$16:$M$22,5, FALSE) -> 1 | Y8: =V8+W8*(P8-X8) -> 18.478 | Z8: =$Z$2*AI8 -> 11.94 | AA8: =M8+Y8+Z8 -> 79.543238 | AB8: 0.15 | AC8: =(1-AB8)*15% + 3%*AB8 -> 0.132 | AD8: 0.25 | AE8: 0.15 | AF8: =AB8+AC8+AD8+AE8 -> 0.682 | AG8: =1-AF8 -> 0.318 | AH8: =AA8/AG8 -> 250.13597 | AI8: 199 | AJ8: 0.25 | AK8: 0.15 | AL8: =M8/AI8 -> 0.24686049 | AM8: =1-AJ8-AK8-AC8-(Y8+Z8)/AI8 -> 0.31514573 | AN8: =1-AJ8-AK8-AC8-AA8/AI8 -> 0.068285236 | AO8: =AN8+AJ8 -> 0.31828524 | AP8: =Y8/AI8 -> 0.092854271 | AQ8: =AI8*AN8/M8 -> 0.27661468
A9: ET009 | B9: Universe | C9: 15.5 | D9: 13 | E9: 10 | F9: 21.2 | G9: 1800 | H9: 1 | I9: =C9*D9*E9/12^3 -> 1.166088 | J9: =G9/$J$2 -> 21.428571 | K9: =$K$2*I9 -> 8.1626157 | L9: =J9*(1+$L$1)*$L$2 -> 4.1271429 | M9: =L9+K9+J9 -> 33.71833 | N9: =F9 -> 21.2 | O9: =roundup(C9*D9*E9/139,0) -> 15 | P9: =MAX(N9,O9) -> 21.2 | Q9: =if(P9<1,Cockpit!$H$7,if(P9<20,Cockpit!$H$8,if(P9<50,Cockpit!$H$9,if(P9<70,Cockpit!$H$10,if(P9<150,Cockpit!$H$11,Cockpit!$H$12))))) -> 3 | R9: =if(MAX(C9:E9)<15,Cockpit!$L$7,if(MAX(C9:E9)<18,Cockpit!$L$8,if(MAX(C9:E9)<59,Cockpit!$L$9,Cockpit!$L$10))) -> 2 | S9: =if(MEDIAN(C9:E9)<0.12,Cockpit!$L$7,if(MEDIAN(C9:E9)<14,Cockpit!$L$8,if(MEDIAN(C9:E9)<33,Cockpit!$L$9,Cockpit!$L$10))) -> 2 | T9: =if(MIN(C9:E9)<0.75,Cockpit!$L$7,if(MIN(C9:E9)<8,Cockpit!$L$8,if(MIN(C9:E9)<33,Cockpit!$L$9,Cockpit!$L$10))) -> 3 | U9: =MAX(Q9:T9) -> 3 | V9: =VLOOKUP($U9,Cockpit!$H$16:$M$22,3, FALSE) -> 10.65 | W9: =VLOOKUP($U9,Cockpit!$H$16:$M$22,4, FALSE) -> 0.38 | X9: =VLOOKUP($U9,Cockpit!$H$16:$M$22,5, FALSE) -> 1 | Y9: =V9+W9*(P9-X9) -> 18.326 | Z9: =$Z$2*AI9 -> 8.9994 | AA9: =M9+Y9+Z9 -> 61.04373 | AB9: 0.15 | AC9: =(1-AB9)*15% + 3%*AB9 -> 0.132 | AD9: 0.25 | AE9: 0.15 | AF9: =AB9+AC9+AD9+AE9 -> 0.682 | AG9: =1-AF9 -> 0.318 | AH9: =AA9/AG9 -> 191.96142 | AI9: 149.99 | AJ9: 0.25 | AK9: 0.15 | AL9: =M9/AI9 -> 0.22480385 | AM9: =1-AJ9-AK9-AC9-(Y9+Z9)/AI9 -> 0.28581852 | AN9: =1-AJ9-AK9-AC9-AA9/AI9 -> 0.061014667 | AO9: =AN9+AJ9 -> 0.31101467 | AP9: =Y9/AI9 -> 0.12218148 | AQ9: =AI9*AN9/M9 -> 0.27141291
A10: ET012 | B10: Universe | C10: 24.5 | D10: 20 | E10: 6.5 | F10: 21.2 | G10: 1980 | H10: 1 | I10: =C10*D10*E10/12^3 -> 1.8431713 | J10: =G10/$J$2 -> 23.571429 | K10: =$K$2*I10 -> 12.902199 | L10: =J10*(1+$L$1)*$L$2 -> 4.5398571 | M10: =L10+K10+J10 -> 41.013485 | N10: =F10 -> 21.2 | O10: =roundup(C10*D10*E10/139,0) -> 23 | P10: =MAX(N10,O10) -> 23 | Q10: =if(P10<1,Cockpit!$H$7,if(P10<20,Cockpit!$H$8,if(P10<50,Cockpit!$H$9,if(P10<70,Cockpit!$H$10,if(P10<150,Cockpit!$H$11,Cockpit!$H$12))))) -> 3 | R10: =if(MAX(C10:E10)<15,Cockpit!$L$7,if(MAX(C10:E10)<18,Cockpit!$L$8,if(MAX(C10:E10)<59,Cockpit!$L$9,Cockpit!$L$10))) -> 3 | S10: =if(MEDIAN(C10:E10)<0.12,Cockpit!$L$7,if(MEDIAN(C10:E10)<14,Cockpit!$L$8,if(MEDIAN(C10:E10)<33,Cockpit!$L$9,Cockpit!$L$10))) -> 3 | T10: =if(MIN(C10:E10)<0.75,Cockpit!$L$7,if(MIN(C10:E10)<8,Cockpit!$L$8,if(MIN(C10:E10)<33,Cockpit!$L$9,Cockpit!$L$10))) -> 2 | U10: =MAX(Q10:T10) -> 3 | V10: =VLOOKUP($U10,Cockpit!$H$16:$M$22,3, FALSE) -> 10.65 | W10: =VLOOKUP($U10,Cockpit!$H$16:$M$22,4, FALSE) -> 0.38 | X10: =VLOOKUP($U10,Cockpit!$H$16:$M$22,5, FALSE) -> 1 | Y10: =V10+W10*(P10-X10) -> 19.01 | Z10: =$Z$2*AI10 -> 9 | AA10: =M10+Y10+Z10 -> 69.023485 | AB10: 0.15 | AC10: =(1-AB10)*15% + 3%*AB10 -> 0.132 | AD10: 0.25 | AE10: 0.15 | AF10: =AB10+AC10+AD10+AE10 -> 0.682 | AG10: =1-AF10 -> 0.318 | AH10: =AA10/AG10 -> 217.05498 | AI10: 150 | AJ10: 0.25 | AK10: 0.1 | AL10: =M10/AI10 -> 0.27342323 | AM10: =1-AJ10-AK10-AC10-(Y10+Z10)/AI10 -> 0.33126667 | AN10: =1-AJ10-AK10-AC10-AA10/AI10 -> 0.057843435 | AO10: =AN10+AJ10 -> 0.30784343 | AP10: =Y10/AI10 -> 0.12673333 | AQ10: =AI10*AN10/M10 -> 0.21155274
A11: DR005MW | B11: Universe | C11: 14.5 | D11: 15 | E11: 6.5 | F11: 8.8 | G11: 1200 | H11: 1 | I11: =C11*D11*E11/12^3 -> 0.81814236 | J11: =G11/$J$2 -> 14.285714 | K11: =$K$2*I11 -> 5.7269965 | L11: =J11*(1+$L$1)*$L$2 -> 2.7514286 | M11: =L11+K11+J11 -> 22.764139 | N11: =F11 -> 8.8 | O11: =roundup(C11*D11*E11/139,0) -> 11 | P11: =MAX(N11,O11) -> 11 | Q11: =if(P11<1,Cockpit!$H$7,if(P11<20,Cockpit!$H$8,if(P11<50,Cockpit!$H$9,if(P11<70,Cockpit!$H$10,if(P11<150,Cockpit!$H$11,Cockpit!$H$12))))) -> 2 | R11: =if(MAX(C11:E11)<15,Cockpit!$L$7,if(MAX(C11:E11)<18,Cockpit!$L$8,if(MAX(C11:E11)<59,Cockpit!$L$9,Cockpit!$L$10))) -> 2 | S11: =if(MEDIAN(C11:E11)<0.12,Cockpit!$L$7,if(MEDIAN(C11:E11)<14,Cockpit!$L$8,if(MEDIAN(C11:E11)<33,Cockpit!$L$9,Cockpit!$L$10))) -> 3 | T11: =if(MIN(C11:E11)<0.75,Cockpit!$L$7,if(MIN(C11:E11)<8,Cockpit!$L$8,if(MIN(C11:E11)<33,Cockpit!$L$9,Cockpit!$L$10))) -> 2 | U11: =MAX(Q11:T11) -> 3 | V11: =VLOOKUP($U11,Cockpit!$H$16:$M$22,3, FALSE) -> 10.65 | W11: =VLOOKUP($U11,Cockpit!$H$16:$M$22,4, FALSE) -> 0.38 | X11: =VLOOKUP($U11,Cockpit!$H$16:$M$22,5, FALSE) -> 1 | Y11: =V11+W11*(P11-X11) -> 14.45 | Z11: =$Z$2*AI11 -> 5.9994 | AA11: =M11+Y11+Z11 -> 43.213539 | AB11: 0.15 | AC11: =(1-AB11)*15% + 3%*AB11 -> 0.132 | AD11: 0.25 | AE11: 0.15 | AF11: =AB11+AC11+AD11+AE11 -> 0.682 | AG11: =1-AF11 -> 0.318 | AH11: =AA11/AG11 -> 135.89163 | AI11: 99.99 | AJ11: 0.25 | AK11: 0.15 | AL11: =M11/AI11 -> 0.22766416 | AM11: =1-AJ11-AK11-AC11-(Y11+Z11)/AI11 -> 0.26348555 | AN11: =1-AJ11-AK11-AC11-AA11/AI11 -> 0.035821388 | AO11: =AN11+AJ11 -> 0.28582139 | AP11: =Y11/AI11 -> 0.14451445 | AQ11: =AI11*AN11/M11 -> 0.15734312
A12: DR002MTMW | B12: Universe | C12: 14.5 | D12: 14.5 | E12: 26.5 | F12: 19 | G12: 1449.84 | H12: 1 | I12: =C12*D12*E12/12^3 -> 3.22432 | J12: =G12/$J$2 -> 17.26 | K12: =$K$2*I12 -> 22.57024 | L12: =J12*(1+$L$1)*$L$2 -> 3.324276 | M12: =L12+K12+J12 -> 43.154516 | N12: =F12 -> 19 | O12: =roundup(C12*D12*E12/139,0) -> 41 | P12: =MAX(N12,O12) -> 41 | Q12: =if(P12<1,Cockpit!$H$7,if(P12<20,Cockpit!$H$8,if(P12<50,Cockpit!$H$9,if(P12<70,Cockpit!$H$10,if(P12<150,Cockpit!$H$11,Cockpit!$H$12))))) -> 3 | R12: =if(MAX(C12:E12)<15,Cockpit!$L$7,if(MAX(C12:E12)<18,Cockpit!$L$8,if(MAX(C12:E12)<59,Cockpit!$L$9,Cockpit!$L$10))) -> 3 | S12: =if(MEDIAN(C12:E12)<0.12,Cockpit!$L$7,if(MEDIAN(C12:E12)<14,Cockpit!$L$8,if(MEDIAN(C12:E12)<33,Cockpit!$L$9,Cockpit!$L$10))) -> 3 | T12: =if(MIN(C12:E12)<0.75,Cockpit!$L$7,if(MIN(C12:E12)<8,Cockpit!$L$8,if(MIN(C12:E12)<33,Cockpit!$L$9,Cockpit!$L$10))) -> 3 | U12: =MAX(Q12:T12) -> 3 | V12: =VLOOKUP($U12,Cockpit!$H$16:$M$22,3, FALSE) -> 10.65 | W12: =VLOOKUP($U12,Cockpit!$H$16:$M$22,4, FALSE) -> 0.38 | X12: =VLOOKUP($U12,Cockpit!$H$16:$M$22,5, FALSE) -> 1 | Y12: =V12+W12*(P12-X12) -> 25.85 | Z12: =$Z$2*AI12 -> 8.9994 | AA12: =M12+Y12+Z12 -> 78.003916 | AB12: 0.15 | AC12: =(1-AB12)*15% + 3%*AB12 -> 0.132 | AD12: 0.25 | AE12: 0.15 | AF12: =AB12+AC12+AD12+AE12 -> 0.682 | AG12: =1-AF12 -> 0.318 | AH12: =AA12/AG12 -> 245.29533 | AI12: 149.99 | AJ12: 0.15 | AK12: 0.15 | AL12: =M12/AI12 -> 0.28771596 | AM12: =1-AJ12-AK12-AC12-(Y12+Z12)/AI12 -> 0.33565518 | AN12: =1-AJ12-AK12-AC12-AA12/AI12 -> 0.047939222 | AO12: =AN12+AJ12 -> 0.19793922 | AP12: =Y12/AI12 -> 0.17234482 | AQ12: =AI12*AN12/M12 -> 0.16661996
A13: DR001MW | B13: Universe | C13: 14 | D13: 14 | E13: 26 | F13: 11.9 | G13: 1249.92 | H13: 1 | I13: =C13*D13*E13/12^3 -> 2.9490741 | J13: =G13/$J$2 -> 14.88 | K13: =$K$2*I13 -> 20.643519 | L13: =J13*(1+$L$1)*$L$2 -> 2.865888 | M13: =L13+K13+J13 -> 38.389407 | N13: =F13 -> 11.9 | O13: =roundup(C13*D13*E13/139,0) -> 37 | P13: =MAX(N13,O13) -> 37 | Q13: =if(P13<1,Cockpit!$H$7,if(P13<20,Cockpit!$H$8,if(P13<50,Cockpit!$H$9,if(P13<70,Cockpit!$H$10,if(P13<150,Cockpit!$H$11,Cockpit!$H$12))))) -> 3 | R13: =if(MAX(C13:E13)<15,Cockpit!$L$7,if(MAX(C13:E13)<18,Cockpit!$L$8,if(MAX(C13:E13)<59,Cockpit!$L$9,Cockpit!$L$10))) -> 3 | S13: =if(MEDIAN(C13:E13)<0.12,Cockpit!$L$7,if(MEDIAN(C13:E13)<14,Cockpit!$L$8,if(MEDIAN(C13:E13)<33,Cockpit!$L$9,Cockpit!$L$10))) -> 3 | T13: =if(MIN(C13:E13)<0.75,Cockpit!$L$7,if(MIN(C13:E13)<8,Cockpit!$L$8,if(MIN(C13:E13)<33,Cockpit!$L$9,Cockpit!$L$10))) -> 3 | U13: =MAX(Q13:T13) -> 3 | V13: =VLOOKUP($U13,Cockpit!$H$16:$M$22,3, FALSE) -> 10.65 | W13: =VLOOKUP($U13,Cockpit!$H$16:$M$22,4, FALSE) -> 0.38 | X13: =VLOOKUP($U13,Cockpit!$H$16:$M$22,5, FALSE) -> 1 | Y13: =V13+W13*(P13-X13) -> 24.33 | Z13: =$Z$2*AI13 -> 8.3994 | AA13: =M13+Y13+Z13 -> 71.118807 | AB13: 0.15 | AC13: =(1-AB13)*15% + 3%*AB13 -> 0.132 | AD13: 0.25 | AE13: 0.15 | AF13: =AB13+AC13+AD13+AE13 -> 0.682 | AG13: =1-AF13 -> 0.318 | AH13: =AA13/AG13 -> 223.64405 | AI13: 139.99 | AJ13: 0.15 | AK13: 0.15 | AL13: =M13/AI13 -> 0.27422963 | AM13: =1-AJ13-AK13-AC13-(Y13+Z13)/AI13 -> 0.33420187 | AN13: =1-AJ13-AK13-AC13-AA13/AI13 -> 0.059972237 | AO13: =AN13+AJ13 -> 0.20997224 | AP13: =Y13/AI13 -> 0.17379813 | AQ13: =AI13*AN13/M13 -> 0.21869349
A14: DR004MB | B14: Kill | C14: 14.5 | D14: 14.5 | E14: 7.5 | F14: 10.4 | G14: 1250 | H14: 1 | I14: =C14*D14*E14/12^3 -> 0.9125434 | J14: =G14/$J$2 -> 14.880952 | K14: =$K$2*I14 -> 6.3878038 | L14: =J14*(1+$L$1)*$L$2 -> 2.8660714 | M14: =L14+K14+J14 -> 24.134828 | N14: =F14 -> 10.4 | O14: =roundup(C14*D14*E14/139,0) -> 12 | P14: =MAX(N14,O14) -> 12 | Q14: =if(P14<1,Cockpit!$H$7,if(P14<20,Cockpit!$H$8,if(P14<50,Cockpit!$H$9,if(P14<70,Cockpit!$H$10,if(P14<150,Cockpit!$H$11,Cockpit!$H$12))))) -> 2 | R14: =if(MAX(C14:E14)<15,Cockpit!$L$7,if(MAX(C14:E14)<18,Cockpit!$L$8,if(MAX(C14:E14)<59,Cockpit!$L$9,Cockpit!$L$10))) -> 1 | S14: =if(MEDIAN(C14:E14)<0.12,Cockpit!$L$7,if(MEDIAN(C14:E14)<14,Cockpit!$L$8,if(MEDIAN(C14:E14)<33,Cockpit!$L$9,Cockpit!$L$10))) -> 3 | T14: =if(MIN(C14:E14)<0.75,Cockpit!$L$7,if(MIN(C14:E14)<8,Cockpit!$L$8,if(MIN(C14:E14)<33,Cockpit!$L$9,Cockpit!$L$10))) -> 2 | U14: =MAX(Q14:T14) -> 3 | V14: =VLOOKUP($U14,Cockpit!$H$16:$M$22,3, FALSE) -> 10.65 | W14: =VLOOKUP($U14,Cockpit!$H$16:$M$22,4, FALSE) -> 0.38 | X14: =VLOOKUP($U14,Cockpit!$H$16:$M$22,5, FALSE) -> 1 | Y14: =V14+W14*(P14-X14) -> 14.83 | Z14: =$Z$2*AI14 -> 4.1994 | AA14: =M14+Y14+Z14 -> 43.164228 | AB14: 0.15 | AC14: =(1-AB14)*15% + 3%*AB14 -> 0.132 | AD14: 0.25 | AE14: 0.15 | AF14: =AB14+AC14+AD14+AE14 -> 0.682 | AG14: =1-AF14 -> 0.318 | AH14: =AA14/AG14 -> 135.73656 | AI14: 69.99 | AJ14: 0.25 | AK14: 0.1 | AL14: =M14/AI14 -> 0.34483251 | AM14: =1-AJ14-AK14-AC14-(Y14+Z14)/AI14 -> 0.24611259 | AN14: =1-AJ14-AK14-AC14-AA14/AI14 -> -0.098719926 | AO14: =AN14+AJ14 -> 0.15128007 | AP14: =Y14/AI14 -> 0.21188741 | AQ14: =AI14*AN14/M14 -> -0.28628369
A15: ET067MB | C15: 24 | D15: 20.5 | E15: 6.5 | F15: 18.0779 | G15: =2500*0.65 -> 1625 | H15: 1 | I15: =C15*D15*E15/12^3 -> 1.8506944 | J15: =G15/$J$2 -> 19.345238 | K15: =$K$2*I15 -> 12.954861 | L15: =J15*(1+$L$1)*$L$2 -> 3.7258929 | M15: =L15+K15+J15 -> 36.025992 | N15: =F15 -> 18.0779 | O15: =roundup(C15*D15*E15/139,0) -> 24 | P15: =MAX(N15,O15) -> 24 | Q15: =if(P15<1,Cockpit!$H$7,if(P15<20,Cockpit!$H$8,if(P15<50,Cockpit!$H$9,if(P15<70,Cockpit!$H$10,if(P15<150,Cockpit!$H$11,Cockpit!$H$12))))) -> 3 | R15: =if(MAX(C15:E15)<15,Cockpit!$L$7,if(MAX(C15:E15)<18,Cockpit!$L$8,if(MAX(C15:E15)<59,Cockpit!$L$9,Cockpit!$L$10))) -> 3 | S15: =if(MEDIAN(C15:E15)<0.12,Cockpit!$L$7,if(MEDIAN(C15:E15)<14,Cockpit!$L$8,if(MEDIAN(C15:E15)<33,Cockpit!$L$9,Cockpit!$L$10))) -> 3 | T15: =if(MIN(C15:E15)<0.75,Cockpit!$L$7,if(MIN(C15:E15)<8,Cockpit!$L$8,if(MIN(C15:E15)<33,Cockpit!$L$9,Cockpit!$L$10))) -> 2 | U15: =MAX(Q15:T15) -> 3 | V15: =VLOOKUP($U15,Cockpit!$H$16:$M$22,3, FALSE) -> 10.65 | W15: =VLOOKUP($U15,Cockpit!$H$16:$M$22,4, FALSE) -> 0.38 | X15: =VLOOKUP($U15,Cockpit!$H$16:$M$22,5, FALSE) -> 1 | Y15: =V15+W15*(P15-X15) -> 19.39 | Z15: =$Z$2*AI15 -> 8.9994 | AA15: =M15+Y15+Z15 -> 64.415392 | AB15: 0.15 | AC15: =(1-AB15)*15% + 3%*AB15 -> 0.132 | AD15: 0.25 | AE15: 0.15 | AF15: =AB15+AC15+AD15+AE15 -> 0.682 | AG15: =1-AF15 -> 0.318 | AH15: =AA15/AG15 -> 202.56413 | AI15: 149.99 | AJ15: 0.25 | AK15: 0.15 | AL15: =M15/AI15 -> 0.24018929 | AM15: =1-AJ15-AK15-AC15-(Y15+Z15)/AI15 -> 0.27872472 | AN15: =1-AJ15-AK15-AC15-AA15/AI15 -> 0.038535422 | AO15: =AN15+AJ15 -> 0.28853542 | AP15: =Y15/AI15 -> 0.12927528 | AQ15: =AI15*AN15/M15 -> 0.16043772
A16: DR003MW | B16: Kill | C16: 14.5 | D16: 15 | E16: 5.5 | F16: 7.7 | G16: 1150 | H16: 1 | I16: =C16*D16*E16/12^3 -> 0.69227431 | J16: =G16/$J$2 -> 13.690476 | K16: =$K$2*I16 -> 4.8459201 | L16: =J16*(1+$L$1)*$L$2 -> 2.6367857 | M16: =L16+K16+J16 -> 21.173182 | N16: =F16 -> 7.7 | O16: =roundup(C16*D16*E16/139,0) -> 9 | P16: =MAX(N16,O16) -> 9 | Q16: =if(P16<1,Cockpit!$H$7,if(P16<20,Cockpit!$H$8,if(P16<50,Cockpit!$H$9,if(P16<70,Cockpit!$H$10,if(P16<150,Cockpit!$H$11,Cockpit!$H$12))))) -> 2 | R16: =if(MAX(C16:E16)<15,Cockpit!$L$7,if(MAX(C16:E16)<18,Cockpit!$L$8,if(MAX(C16:E16)<59,Cockpit!$L$9,Cockpit!$L$10))) -> 2 | S16: =if(MEDIAN(C16:E16)<0.12,Cockpit!$L$7,if(MEDIAN(C16:E16)<14,Cockpit!$L$8,if(MEDIAN(C16:E16)<33,Cockpit!$L$9,Cockpit!$L$10))) -> 3 | T16: =if(MIN(C16:E16)<0.75,Cockpit!$L$7,if(MIN(C16:E16)<8,Cockpit!$L$8,if(MIN(C16:E16)<33,Cockpit!$L$9,Cockpit!$L$10))) -> 2 | U16: =MAX(Q16:T16) -> 3 | V16: =VLOOKUP($U16,Cockpit!$H$16:$M$22,3, FALSE) -> 10.65 | W16: =VLOOKUP($U16,Cockpit!$H$16:$M$22,4, FALSE) -> 0.38 | X16: =VLOOKUP($U16,Cockpit!$H$16:$M$22,5, FALSE) -> 1 | Y16: =V16+W16*(P16-X16) -> 13.69 | Z16: =$Z$2*AI16 -> 3.5994 | AA16: =M16+Y16+Z16 -> 38.462582 | AB16: 0.15 | AC16: =(1-AB16)*15% + 3%*AB16 -> 0.132 | AD16: 0.25 | AE16: 0.15 | AF16: =AB16+AC16+AD16+AE16 -> 0.682 | AG16: =1-AF16 -> 0.318 | AH16: =AA16/AG16 -> 120.95152 | AI16: 59.99 | AJ16: 0.25 | AK16: 0.1 | AL16: =M16/AI16 -> 0.35294519 | AM16: =1-AJ16-AK16-AC16-(Y16+Z16)/AI16 -> 0.2297953 | AN16: =1-AJ16-AK16-AC16-AA16/AI16 -> -0.12314989 | AO16: =AN16+AJ16 -> 0.12685011 | AP16: =Y16/AI16 -> 0.2282047 | AQ16: =AI16*AN16/M16 -> -0.34892073
A17: DR003MWW(D) | B17: Kill | C17: 14.5 | D17: 15 | E17: 5.5 | F17: 7.7 | G17: 1150 | H17: 1 | I17: =C17*D17*E17/12^3 -> 0.69227431 | J17: =G17/$J$2 -> 13.690476 | K17: =$K$2*I17 -> 4.8459201 | L17: =J17*(1+$L$1)*$L$2 -> 2.6367857 | M17: =L17+K17+J17 -> 21.173182 | N17: =F17 -> 7.7 | O17: =roundup(C17*D17*E17/139,0) -> 9 | P17: =MAX(N17,O17) -> 9 | Q17: =if(P17<1,Cockpit!$H$7,if(P17<20,Cockpit!$H$8,if(P17<50,Cockpit!$H$9,if(P17<70,Cockpit!$H$10,if(P17<150,Cockpit!$H$11,Cockpit!$H$12))))) -> 2 | R17: =if(MAX(C17:E17)<15,Cockpit!$L$7,if(MAX(C17:E17)<18,Cockpit!$L$8,if(MAX(C17:E17)<59,Cockpit!$L$9,Cockpit!$L$10))) -> 2 | S17: =if(MEDIAN(C17:E17)<0.12,Cockpit!$L$7,if(MEDIAN(C17:E17)<14,Cockpit!$L$8,if(MEDIAN(C17:E17)<33,Cockpit!$L$9,Cockpit!$L$10))) -> 3 | T17: =if(MIN(C17:E17)<0.75,Cockpit!$L$7,if(MIN(C17:E17)<8,Cockpit!$L$8,if(MIN(C17:E17)<33,Cockpit!$L$9,Cockpit!$L$10))) -> 2 | U17: =MAX(Q17:T17) -> 3 | V17: =VLOOKUP($U17,Cockpit!$H$16:$M$22,3, FALSE) -> 10.65 | W17: =VLOOKUP($U17,Cockpit!$H$16:$M$22,4, FALSE) -> 0.38 | X17: =VLOOKUP($U17,Cockpit!$H$16:$M$22,5, FALSE) -> 1 | Y17: =V17+W17*(P17-X17) -> 13.69 | Z17: =$Z$2*AI17 -> 3.5994 | AA17: =M17+Y17+Z17 -> 38.462582 | AB17: 0.15 | AC17: =(1-AB17)*15% + 3%*AB17 -> 0.132 | AD17: 0.25 | AE17: 0.15 | AF17: =AB17+AC17+AD17+AE17 -> 0.682 | AG17: =1-AF17 -> 0.318 | AH17: =AA17/AG17 -> 120.95152 | AI17: 59.99 | AJ17: 0.25 | AK17: 0.1 | AL17: =M17/AI17 -> 0.35294519 | AM17: =1-AJ17-AK17-AC17-(Y17+Z17)/AI17 -> 0.2297953 | AN17: =1-AJ17-AK17-AC17-AA17/AI17 -> -0.12314989 | AO17: =AN17+AJ17 -> 0.12685011 | AP17: =Y17/AI17 -> 0.2282047 | AQ17: =AI17*AN17/M17 -> -0.34892073
A18: ET043MTMS | B18: Kill | C18: 26 | D18: 18 | E18: 5.5 | F18: 20.3 | G18: 1200 | H18: 1 | I18: =C18*D18*E18/12^3 -> 1.4895833 | J18: =G18/$J$2 -> 14.285714 | K18: =$K$2*I18 -> 10.427083 | L18: =J18*(1+$L$1)*$L$2 -> 2.7514286 | M18: =L18+K18+J18 -> 27.464226 | N18: =F18 -> 20.3 | O18: =roundup(C18*D18*E18/139,0) -> 19 | P18: =MAX(N18,O18) -> 20.3 | Q18: =if(P18<1,Cockpit!$H$7,if(P18<20,Cockpit!$H$8,if(P18<50,Cockpit!$H$9,if(P18<70,Cockpit!$H$10,if(P18<150,Cockpit!$H$11,Cockpit!$H$12))))) -> 3 | R18: =if(MAX(C18:E18)<15,Cockpit!$L$7,if(MAX(C18:E18)<18,Cockpit!$L$8,if(MAX(C18:E18)<59,Cockpit!$L$9,Cockpit!$L$10))) -> 3 | S18: =if(MEDIAN(C18:E18)<0.12,Cockpit!$L$7,if(MEDIAN(C18:E18)<14,Cockpit!$L$8,if(MEDIAN(C18:E18)<33,Cockpit!$L$9,Cockpit!$L$10))) -> 3 | T18: =if(MIN(C18:E18)<0.75,Cockpit!$L$7,if(MIN(C18:E18)<8,Cockpit!$L$8,if(MIN(C18:E18)<33,Cockpit!$L$9,Cockpit!$L$10))) -> 2 | U18: =MAX(Q18:T18) -> 3 | V18: =VLOOKUP($U18,Cockpit!$H$16:$M$22,3, FALSE) -> 10.65 | W18: =VLOOKUP($U18,Cockpit!$H$16:$M$22,4, FALSE) -> 0.38 | X18: =VLOOKUP($U18,Cockpit!$H$16:$M$22,5, FALSE) -> 1 | Y18: =V18+W18*(P18-X18) -> 17.984 | Z18: =$Z$2*AI18 -> 4.4994 | AA18: =M18+Y18+Z18 -> 49.947626 | AB18: 0.15 | AC18: =(1-AB18)*15% + 3%*AB18 -> 0.132 | AD18: 0.25 | AE18: 0.15 | AF18: =AB18+AC18+AD18+AE18 -> 0.682 | AG18: =1-AF18 -> 0.318 | AH18: =AA18/AG18 -> 157.06801 | AI18: 74.99 | AJ18: 0.25 | AK18: 0.1 | AL18: =M18/AI18 -> 0.36623851 | AM18: =1-AJ18-AK18-AC18-(Y18+Z18)/AI18 -> 0.21818136 | AN18: =1-AJ18-AK18-AC18-AA18/AI18 -> -0.14805716 | AO18: =AN18+AJ18 -> 0.10194284 | AP18: =Y18/AI18 -> 0.23981864 | AQ18: =AI18*AN18/M18 -> -0.4042643
A19: ET005MR | B19: Kill | C19: 20.5 | D19: 20 | E19: 23 | F19: 34.6 | G19: 4200 | H19: 1 | I19: =C19*D19*E19/12^3 -> 5.4571759 | J19: =G19/$J$2 -> 50 | K19: =$K$2*I19 -> 38.200231 | L19: =J19*(1+$L$1)*$L$2 -> 9.63 | M19: =L19+K19+J19 -> 97.830231 | N19: =F19 -> 34.6 | O19: =roundup(C19*D19*E19/139,0) -> 68 | P19: =MAX(N19,O19) -> 68 | Q19: =if(P19<1,Cockpit!$H$7,if(P19<20,Cockpit!$H$8,if(P19<50,Cockpit!$H$9,if(P19<70,Cockpit!$H$10,if(P19<150,Cockpit!$H$11,Cockpit!$H$12))))) -> 5 | R19: =if(MAX(C19:E19)<15,Cockpit!$L$7,if(MAX(C19:E19)<18,Cockpit!$L$8,if(MAX(C19:E19)<59,Cockpit!$L$9,Cockpit!$L$10))) -> 3 | S19: =if(MEDIAN(C19:E19)<0.12,Cockpit!$L$7,if(MEDIAN(C19:E19)<14,Cockpit!$L$8,if(MEDIAN(C19:E19)<33,Cockpit!$L$9,Cockpit!$L$10))) -> 3 | T19: =if(MIN(C19:E19)<0.75,Cockpit!$L$7,if(MIN(C19:E19)<8,Cockpit!$L$8,if(MIN(C19:E19)<33,Cockpit!$L$9,Cockpit!$L$10))) -> 3 | U19: =MAX(Q19:T19) -> 5 | V19: =VLOOKUP($U19,Cockpit!$H$16:$M$22,3, FALSE) -> 40.12 | W19: =VLOOKUP($U19,Cockpit!$H$16:$M$22,4, FALSE) -> 0.75 | X19: =VLOOKUP($U19,Cockpit!$H$16:$M$22,5, FALSE) -> 51 | Y19: =V19+W19*(P19-X19) -> 52.87 | Z19: =$Z$2*AI19 -> 14.9994 | AA19: =M19+Y19+Z19 -> 165.69963 | AB19: 0.15 | AC19: =(1-AB19)*15% + 3%*AB19 -> 0.132 | AD19: 0.25 | AE19: 0.15 | AF19: =AB19+AC19+AD19+AE19 -> 0.682 | AG19: =1-AF19 -> 0.318 | AH19: =AA19/AG19 -> 521.06802 | AI19: 249.99 | AJ19: 0.25 | AK19: 0.15 | AL19: =M19/AI19 -> 0.39133658 | AM19: =1-AJ19-AK19-AC19-(Y19+Z19)/AI19 -> 0.19651154 | AN19: =1-AJ19-AK19-AC19-AA19/AI19 -> -0.19482504 | AO19: =AN19+AJ19 -> 0.055174961 | AP19: =Y19/AI19 -> 0.21148846 | AQ19: =AI19*AN19/M19 -> -0.4978452
A20: ET004 | B20: Kill | C20: 19 | D20: 19 | E20: 23 | G20: 2700 | H20: 1 | I20: =C20*D20*E20/12^3 -> 4.8049769 | J20: =G20/$J$2 -> 32.142857 | K20: =$K$2*I20 -> 33.634838 | L20: =J20*(1+$L$1)*$L$2 -> 6.1907143 | M20: =L20+K20+J20 -> 71.968409 | N20: =F20 | O20: =roundup(C20*D20*E20/139,0) -> 60 | P20: =MAX(N20,O20) -> 60 | Q20: =if(P20<1,Cockpit!$H$7,if(P20<20,Cockpit!$H$8,if(P20<50,Cockpit!$H$9,if(P20<70,Cockpit!$H$10,if(P20<150,Cockpit!$H$11,Cockpit!$H$12))))) -> 5 | R20: =if(MAX(C20:E20)<15,Cockpit!$L$7,if(MAX(C20:E20)<18,Cockpit!$L$8,if(MAX(C20:E20)<59,Cockpit!$L$9,Cockpit!$L$10))) -> 3 | S20: =if(MEDIAN(C20:E20)<0.12,Cockpit!$L$7,if(MEDIAN(C20:E20)<14,Cockpit!$L$8,if(MEDIAN(C20:E20)<33,Cockpit!$L$9,Cockpit!$L$10))) -> 3 | T20: =if(MIN(C20:E20)<0.75,Cockpit!$L$7,if(MIN(C20:E20)<8,Cockpit!$L$8,if(MIN(C20:E20)<33,Cockpit!$L$9,Cockpit!$L$10))) -> 3 | U20: =MAX(Q20:T20) -> 5 | V20: =VLOOKUP($U20,Cockpit!$H$16:$M$22,3, FALSE) -> 40.12 | W20: =VLOOKUP($U20,Cockpit!$H$16:$M$22,4, FALSE) -> 0.75 | X20: =VLOOKUP($U20,Cockpit!$H$16:$M$22,5, FALSE) -> 51 | Y20: =V20+W20*(P20-X20) -> 46.87 | Z20: =$Z$2*AI20 -> 14.9994 | AA20: =M20+Y20+Z20 -> 133.83781 | AB20: 0.15 | AC20: =(1-AB20)*15% + 3%*AB20 -> 0.132 | AD20: 0.25 | AE20: 0.15 | AF20: =AB20+AC20+AD20+AE20 -> 0.682 | AG20: =1-AF20 -> 0.318 | AH20: =AA20/AG20 -> 420.87361 | AI20: =249.99 -> 249.99 | AJ20: 0.25 | AK20: 0.15 | AL20: =M20/AI20 -> 0.28788515 | AM20: =1-AJ20-AK20-AC20-(Y20+Z20)/AI20 -> 0.2205125 | AN20: =1-AJ20-AK20-AC20-AA20/AI20 -> -0.067372652 | AO20: =AN20+AJ20 -> 0.18262735 | AP20: =Y20/AI20 -> 0.1874875 | AQ20: =AI20*AN20/M20 -> -0.23402614
A21: ET006 | B21: Kill | C21: 17 | D21: 17 | E21: 23 | F21: 38.8 | G21: 5100 | H21: 1 | I21: =C21*D21*E21/12^3 -> 3.8466435 | J21: =G21/$J$2 -> 60.714286 | K21: =$K$2*I21 -> 26.926505 | L21: =J21*(1+$L$1)*$L$2 -> 11.693571 | M21: =L21+K21+J21 -> 99.334362 | N21: =F21 -> 38.8 | O21: =roundup(C21*D21*E21/139,0) -> 48 | P21: =MAX(N21,O21) -> 48 | Q21: =if(P21<1,Cockpit!$H$7,if(P21<20,Cockpit!$H$8,if(P21<50,Cockpit!$H$9,if(P21<70,Cockpit!$H$10,if(P21<150,Cockpit!$H$11,Cockpit!$H$12))))) -> 3 | R21: =if(MAX(C21:E21)<15,Cockpit!$L$7,if(MAX(C21:E21)<18,Cockpit!$L$8,if(MAX(C21:E21)<59,Cockpit!$L$9,Cockpit!$L$10))) -> 3 | S21: =if(MEDIAN(C21:E21)<0.12,Cockpit!$L$7,if(MEDIAN(C21:E21)<14,Cockpit!$L$8,if(MEDIAN(C21:E21)<33,Cockpit!$L$9,Cockpit!$L$10))) -> 3 | T21: =if(MIN(C21:E21)<0.75,Cockpit!$L$7,if(MIN(C21:E21)<8,Cockpit!$L$8,if(MIN(C21:E21)<33,Cockpit!$L$9,Cockpit!$L$10))) -> 3 | U21: =MAX(Q21:T21) -> 3 | V21: =VLOOKUP($U21,Cockpit!$H$16:$M$22,3, FALSE) -> 10.65 | W21: =VLOOKUP($U21,Cockpit!$H$16:$M$22,4, FALSE) -> 0.38 | X21: =VLOOKUP($U21,Cockpit!$H$16:$M$22,5, FALSE) -> 1 | Y21: =V21+W21*(P21-X21) -> 28.51 | Z21: =$Z$2*AI21 -> 13.7994 | AA21: =M21+Y21+Z21 -> 141.64376 | AB21: 0.15 | AC21: =(1-AB21)*15% + 3%*AB21 -> 0.132 | AD21: 0.25 | AE21: 0.15 | AF21: =AB21+AC21+AD21+AE21 -> 0.682 | AG21: =1-AF21 -> 0.318 | AH21: =AA21/AG21 -> 445.42063 | AI21: 229.99 | AJ21: 0.25 | AK21: 0.15 | AL21: =M21/AI21 -> 0.43190731 | AM21: =1-AJ21-AK21-AC21-(Y21+Z21)/AI21 -> 0.28403809 | AN21: =1-AJ21-AK21-AC21-AA21/AI21 -> -0.14786922 | AO21: =AN21+AJ21 -> 0.10213078 | AP21: =Y21/AI21 -> 0.12396191 | AQ21: =AI21*AN21/M21 -> -0.34236332
A22: ET013 | B22: Kill | C22: 21 | D22: 21 | E22: 25 | F22: 64.3 | G22: 4000 | H22: 1 | I22: =C22*D22*E22/12^3 -> 6.3802083 | J22: =G22/$J$2 -> 47.619048 | K22: =$K$2*I22 -> 44.661458 | L22: =J22*(1+$L$1)*$L$2 -> 9.1714286 | M22: =L22+K22+J22 -> 101.45193 | N22: =F22 -> 64.3 | O22: =roundup(C22*D22*E22/139,0) -> 80 | P22: =MAX(N22,O22) -> 80 | Q22: =if(P22<1,Cockpit!$H$7,if(P22<20,Cockpit!$H$8,if(P22<50,Cockpit!$H$9,if(P22<70,Cockpit!$H$10,if(P22<150,Cockpit!$H$11,Cockpit!$H$12))))) -> 6 | R22: =if(MAX(C22:E22)<15,Cockpit!$L$7,if(MAX(C22:E22)<18,Cockpit!$L$8,if(MAX(C22:E22)<59,Cockpit!$L$9,Cockpit!$L$10))) -> 3 | S22: =if(MEDIAN(C22:E22)<0.12,Cockpit!$L$7,if(MEDIAN(C22:E22)<14,Cockpit!$L$8,if(MEDIAN(C22:E22)<33,Cockpit!$L$9,Cockpit!$L$10))) -> 3 | T22: =if(MIN(C22:E22)<0.75,Cockpit!$L$7,if(MIN(C22:E22)<8,Cockpit!$L$8,if(MIN(C22:E22)<33,Cockpit!$L$9,Cockpit!$L$10))) -> 3 | U22: =MAX(Q22:T22) -> 6 | V22: =VLOOKUP($U22,Cockpit!$H$16:$M$22,3, FALSE) -> 54.81 | W22: =VLOOKUP($U22,Cockpit!$H$16:$M$22,4, FALSE) -> 0.75 | X22: =VLOOKUP($U22,Cockpit!$H$16:$M$22,5, FALSE) -> 71 | Y22: =V22+W22*(P22-X22) -> 61.56 | Z22: =$Z$2*AI22 -> 11.9994 | AA22: =M22+Y22+Z22 -> 175.01133 | AB22: 0.15 | AC22: =(1-AB22)*15% + 3%*AB22 -> 0.132 | AD22: 0.25 | AE22: 0.15 | AF22: =AB22+AC22+AD22+AE22 -> 0.682 | AG22: =1-AF22 -> 0.318 | AH22: =AA22/AG22 -> 550.35011 | AI22: 199.99 | AJ22: 0.25 | AK22: 0.15 | AL22: =M22/AI22 -> 0.50728504 | AM22: =1-AJ22-AK22-AC22-(Y22+Z22)/AI22 -> 0.10018461 | AN22: =1-AJ22-AK22-AC22-AA22/AI22 -> -0.40710043 | AO22: =AN22+AJ22 -> -0.15710043 | AP22: =Y22/AI22 -> 0.30781539 | AQ22: =AI22*AN22/M22 -> -0.80250825

Sheet invoice values
A1: ='Amazon Model Unit Economics - V'!A3 -> SKU | B1: ='Amazon Model Unit Economics - V'!J3 -> Ex-factory cost | C1: Invoice value
A2: ='Amazon Model Unit Economics - V'!A4 -> ET008 | B2: ='Amazon Model Unit Economics - V'!J4 -> 26.190476 | C2: =B2*1.07 -> 28.02381
A3: ='Amazon Model Unit Economics - V'!A5 -> ET042MB(D) | B3: ='Amazon Model Unit Economics - V'!J5 -> 19.642857 | C3: =B3*1.07 -> 21.017857
A4: ='Amazon Model Unit Economics - V'!A6 -> ET042MW | B4: ='Amazon Model Unit Economics - V'!J6 -> 19.642857 | C4: =B4*1.07 -> 21.017857
A5: ='Amazon Model Unit Economics - V'!A7 -> ET003-N | B5: ='Amazon Model Unit Economics - V'!J7 -> 32.142857 | C5: =B5*1.07 -> 34.392857
A6: ='Amazon Model Unit Economics - V'!A8 -> ET003-W | B6: ='Amazon Model Unit Economics - V'!J8 -> 32.142857 | C6: =B6*1.07 -> 34.392857
A7: ='Amazon Model Unit Economics - V'!A9 -> ET009 | B7: ='Amazon Model Unit Economics - V'!J9 -> 21.428571 | C7: =B7*1.07 -> 22.928571
A8: ='Amazon Model Unit Economics - V'!A10 -> ET012 | B8: ='Amazon Model Unit Economics - V'!J10 -> 23.571429 | C8: =B8*1.07 -> 25.221429
A9: ='Amazon Model Unit Economics - V'!A11 -> DR005MW | B9: ='Amazon Model Unit Economics - V'!J11 -> 14.285714 | C9: =B9*1.07 -> 15.285714
A10: ='Amazon Model Unit Economics - V'!A12 -> DR002MTMW | B10: ='Amazon Model Unit Economics - V'!J12 -> 17.26 | C10: =B10*1.07 -> 18.4682
A11: ='Amazon Model Unit Economics - V'!A13 -> DR001MW | B11: ='Amazon Model Unit Economics - V'!J13 -> 14.88 | C11: =B11*1.07 -> 15.9216
A12: ='Amazon Model Unit Economics - V'!A14 -> DR004MB | B12: ='Amazon Model Unit Economics - V'!J14 -> 14.880952 | C12: =B12*1.07 -> 15.922619
A13: ='Amazon Model Unit Economics - V'!A15 -> ET067MB | B13: ='Amazon Model Unit Economics - V'!J15 -> 19.345238 | C13: =B13*1.07 -> 20.699405
... A20: ='Amazon Model Unit Economics - V'!A22 -> ET013 | B20: ='Amazon Model Unit Economics - V'!J22 -> 47.619048 | C20: =B20*1.07 -> 50.952381
A21: ='Amazon Model Unit Economics - V'!A23
A22: ='Amazon Model Unit Economics - V'!A24
A23: ='Amazon Model Unit Economics - V'!A25
A24: ='Amazon Model Unit Economics - V'!A26
A25: ='Amazon Model Unit Economics - V'!A27
A26: ='Amazon Model Unit Economics - V'!A28

Sheet Sheet13
B3: SKU | C3: ASP (Target selling Price) | D3: Net Margin% basis Target Selling Price | E3: Current Units
B4: ET008 | C4: 199.99 | D4: 0.078502662 | E4: 20
B5: ET042MB(D) | C5: 149.99 | D5: 0.074857552 | E5: 35
B6: ET042MW | C6: 149.99 | D6: 0.074857552 | E6: 35
B7: ET003-W | C7: 199 | D7: 0.073470089 | E7: 25
B8: ET003-N | C8: 199 | D8: 0.073470089 | E8: 25
B9: ET009 | C9: 149.99 | D9: 0.065600687 | E9: 30
B10: ET012 | C10: 150 | D10: 0.06288772 | E10: 22
B11: DR005MW | C11: 99.99 | D11: 0.040407561 | E11: 25
B12: DR001MW | C12: 139.99 | D12: 0.04 | E12: 25
B13: DR002MTMW | C13: 149.99 | D13: 0.04 | E13: 25

Sheet Cockpit
B2: USD to INR Conversion | C2: 84
B3: Number of months for storage | C3: 2
B4: PA WH Storage cost per month per CFT (USD) | C4: 0.45
C6: INR | D6: USD | G6: Max Shipping Weight (lb) | H6: Class | I6: Shipping tier | K6: Longest side (in)
B7: Ind WH to Ind Port | C7: 100000 | D7: =C7/$C$2 -> 1190.4762 | G7: 16 | H7: 1 | I7: Small standard size | K7: 15 | L7: 1 | M7: Small standard size
G8: 20 | H8: 2 | I8: Large standard size | K8: 18 | L8: 2 | M8: Large standard size
G9: 50 | H9: 3 | I9: Large bulky | K9: 59 | L9: 3 | M9: Large bulky
D10: =8000-D7 -> 6809.5238 | G10: 70 | H10: 5 | I10: Extra large bulky | L10: 4 | M10: Extra large bulky
B11: India WH to PA-WH logistics cost | D11: =SUM(D7:D10) -> 8000 | G11: 150 | H11: 6 | I11: Extra large bulky (70 to 150lbs)
I15: Shipping tier | J15: Base Charges | K15: Incremental charges
H16: 1 | I16: Small standard size
H17: 2 | I17: Large standard size | J17: 7.46 | K17: =0.08*4 -> 0.32 | L17: 3
H18: 3 | I18: Large bulky | J18: 10.65 | K18: 0.38 | L18: 1
H19: 4 | I19: Extra large bulky (0 to 50lbs) | J19: 26.33 | K19: 0.38 | L19: 1
H20: 5 | I20: Extra large bulky (50 to 70lbs) | J20: 40.12 | K20: 0.75 | L20: 51
H21: 6 | I21: Extra large bulky (70 to 150lbs) | J21: 54.81 | K21: 0.75 | L21: 71
H22: 7 | I22: Extra large bulky (150lbs+) | J22: 194.95 | K22: 0.19 | L22: 151
I41: FBA Non-peak Fulfillment Fees (excluding apparel)
B42: 2025 Peak Fulfillment fees (excluding apparel) (October 15, 2025 – January 14, 2026) | K42: January 15, 2025 – October 14, 2025 | N42: Starting January 15, 2026
B43: Size tier | C43: Shipping weight | D43: <$10 | E43: $10-$50 | F43: >$50 | I43: Size tier | J43: Shipping weight | K43: <$10 | L43: $10-$50 | M43: >$50 | N43: <$10 | O43: $10-$50 | P43: >$50
B44: Large standard | C44: 4 oz or less | D44: 3.15 | E44: 3.92 | F44: 3.92 | I44: Large standard | J44: 4 oz or less | K44: 2.91 | L44: 3.68 | M44: 3.68 | N44: 2.91 | O44: 3.73 | P44: 3.99
C45: 4+ to 8 oz | D45: 3.39 | E45: 4.16 | F45: 4.16 | J45: 4+ to 8 oz | K45: 3.13 | L45: 3.9 | M45: 3.9 | N45: 3.13 | O45: 3.95 | P45: 4.21
C46: 8+ to 12 oz | D46: 3.66 | E46: 4.43 | F46: 4.43 | J46: 8+ to 12 oz | K46: 3.38 | L46: 4.15 | M46: 4.15 | N46: 3.38 | O46: 4.2 | P46: 4.46
C47: 12+ to 16 oz | D47: 4.07 | E47: 4.84 | F47: 4.84 | J47: 12+ to 16 oz | K47: 3.78 | L47: 4.55 | M47: 4.55 | N47: 3.78 | O47: 4.6 | P47: 4.86
C48: 1+ to 1.25 lb | D48: 4.52 | E48: 5.29 | F48: 5.29 | J48: 1+ to 1.25 lb | K48: 4.22 | L48: 4.99 | M48: 4.99 | N48: 4.22 | O48: 5.04 | P48: 5.3
C49: 1.25+ to 1.5 lb | D49: 4.91 | E49: 5.68 | F49: 5.68 | J49: 1.25+ to 1.5 lb | K49: 4.6 | L49: 5.37 | M49: 5.37 | N49: 4.6 | O49: 5.42 | P49: 5.68
C50: 1.5+ to 1.75 lb | D50: 5.07 | E50: 5.84 | F50: 5.84 | J50: 1.5+ to 1.75 lb | K50: 4.75 | L50: 5.52 | M50: 5.52 | N50: 4.75 | O50: 5.57 | P50: 5.83
C51: 1.75+ to 2 lb | D51: 5.33 | E51: 6.1 | F51: 6.1 | J51: 1.75+ to 2 lb | K51: 5 | L51: 5.77 | M51: 5.77 | N51: 5 | O51: 5.82 | P51: 6.08
C52: 2+ to 2.25 lb | D52: 5.47 | E52: 6.24 | F52: 6.24 | J52: 2+ to 2.25 lb | K52: 5.1 | L52: 5.87 | M52: 5.87 | N52: 5.1 | O52: 5.92 | P52: 6.18
C53: 2.25+ to 2.5 lb | D53: 5.67 | E53: 6.44 | F53: 6.44 | J53: 2.25+ to 2.5 lb | K53: 5.28 | L53: 6.05 | M53: 6.05 | N53: 5.28 | O53: 6.1 | P53: 6.36
C54: 2.5+ to 2.75 lb | D54: 5.84 | E54: 6.61 | F54: 6.61 | J54: 2.5+ to 2.75 lb | K54: 5.44 | L54: 6.21 | M54: 6.21 | N54: 5.44 | O54: 6.26 | P54: 6.52
C55: 2.75+ to 3 lb | D55: 6.26 | E55: 7.03 | F55: 7.03 | J55: 2.75+ to 3 lb | K55: 5.85 | L55: 6.62 | M55: 6.62 | N55: 5.85 | O55: 6.67 | P55: 6.93
C56: 3+ lb to 20 lb | D56: $6.69 + $0.08 per 4 oz interval above first 3 lb | E56: $7.46 + $0.08 per 4 oz interval above first 3 lb | F56: $7.46 + $0.08 per 4 oz interval above first 3 lb | J56: 3+ lb to 20 lb | K56: $6.15 + $0.08 per 4 oz interval above first 3 lb | L56: $6.92 + $0.08 per 4 oz interval above first 3 lb | M56: $6.92 + $0.08 per 4 oz interval above first 3 lb | N56: $6.15 + $0.08 per 4 oz interval above first 3 lb | O56: $6.97 + $0.08 per 4 oz interval above first 3 lb | P56: $7.23 + $0.08 per 4 oz interval above first 3 lb
B57: Small Bulky | C57: 0 to 50 lb | D57: $9.88 + $0.38/lb interval above first lb | E57: $10.65 + $0.38/lb interval above first lb | F57: $10.65 + $0.38/lb interval above first lb | I57: Small Bulky | J57: 0 to 50 lb | K57: $8.84 + $0.38/lb interval above first lb | L57: $9.61 + $0.38/lb interval above first lb | M57: $9.61 + $0.38/lb interval above first lb | N57: $6.78 + $0.38/lb interval above first lb | O57: $7.55 + $0.38/lb interval above first lb | P57: $7.55 + $0.38/lb interval above first lb
I58: Large Bulky | J58: 0 to 50 lb | K58: $8.84 + $0.38/lb interval above first lb | L58: $9.61 + $0.38/lb interval above first lb | M58: $9.61 + $0.38/lb interval above first lb | N58: $8.58 + $0.38/lb interval above first lb | O58: $9.35 + $0.38/lb interval above first lb | P58: $9.35 + $0.38/lb interval above first lb
I59: Extra-large 0 to 50 lb | J59: 0 to 50 lb | K59: $25.56 + $0.38/lb interval above first lb | L59: $26.33 + $0.38/lb interval above first lb | M59: $26.33 + $0.38/lb interval above first lb | N59: $25.56 + $0.38/lb interval above first lb | O59: $26.33 + $0.38/lb interval above first lb | P59: $26.33 + $0.38/lb interval above first lb
I60: Extra-large 50+ to 70 lb | J60: 50+ to 70 lb | K60: $39.35 + $0.75/lb interval above 51 lb | L60: $40.12 + $0.75/lb interval above 51 lb | M60: $40.12 + $0.75/lb interval above 51 lb | N60: $36.55 + $0.75/lb interval above 51 lb | O60: $37.32 + $0.75/lb interval above 51 lb | P60: $37.32 + $0.75/lb interval above 51 lb
I61: Extra-large 70+ to 150 lb | J61: 70+ to 150 lb | K61: $54.04 + $0.75/lb interval above 71 lb | L61: $54.81 + $0.75/lb interval above 71 lb | M61: $54.81 + $0.75/lb interval above 71 lb | N61: $50.55 + $0.75/lb interval above 71 lb | O61: $51.32 + $0.75/lb interval above 71 lb | P61: $51.32 + $0.75/lb interval above 71 lb
I62: Extra-large 150+ lb1 | J62: 150+ lb | K62: $194.18 + $0.19/lb interval above 151 lb | L62: $194.95 + $0.19/lb interval above 151 lb | M62: $194.95 + $0.19/lb interval above 151 lb | N62: $194.18 + $0.19/lb interval above 151 lb | O62: $194.95 + $0.19/lb interval above 151 lb | P62: $194.95 + $0.19/lb interval above 151 lb
B68: 2024 Product size tier definitions (ending on January 14, 2026) | I68: 2026 product size tier definitions (starting on January 15, 2026)
...

Sheet Amazon Unit Economics Model - V
F2: $7 per CFT | M2: 15% of net + 3% return admin on returned items | Q2: 25% of Gross sales | R2: 5% of Gross sales | W2: Net COGS in dollars calculated on gross sale units as returns will not be resold
F3: 7 | J3: 0.15 | M3: 0.15 | Q3: 0.25 | R3: 0.055
B4: SKU | C4: KD/Non-KD | D4: Factory price | E4: CFT | F4: SEND Shipping | G4: ASP | H4: Gross Units | I4: Gross Sales | J4: Return % | K4: Net Units | L4: Net Sales | M4: AZ Selling Fees | N4: FBA Fulfilment Fees | O4: AZ Fulfillment fees | P4: OM1 | Q4: Ads | R4: Other costs | S4: Profit Before COGS | T4: Unit COGS 0% Tariff | U4: Unit COGS 25% Tariff | V4: Unit COGS 50% Tariff | W4: Gross COGS 0% Tariff | X4: Gross COGS 25% Tariff | Y4: Gross COGS 50% Tariff | Z4: Net Margin 0% Tariff | AA4: Net Margin 25% Tariff | AB4: Net Margin 50% Tariff | AC4: % Net Margin 0% Tariff | AD4: % Net margin 25% Tariff | AE4: % Net margin 50% Tariff | AF4: % returns | AG4: Gross sales (4 months) | AH4: Gross COGS % 0% Tariff | AI4: Gross COGS% 25% Tariff | AJ4: Gross COGS% 50% Tariff | AS4: Returns (4 months)
B5: RH-ET042MB(D)-FBA | C5: KD | D5: 19.64 | E5: =23*6*18/12/12/12 -> 1.4375 | F5: =E5*$F$3 -> 10.0625 | G5: 149.99 | H5: 26 | I5: =G5*H5 -> 3899.74 | J5: =$J$3 -> 0.15 | K5: =rounddown(H5*(1-J5),0) -> 22 | L5: =K5*G5 -> 3299.78 | M5: =L5*$M$3+3%*(H5-K5)*G5 -> 512.9658 | N5: 16.45 | O5: =N5*(H5) -> 427.7 | P5: =L5-M5-O5 -> 2359.1142 | Q5: =I5*$Q$3 -> 974.935 | R5: =I5*$R$3 -> 214.4857 | S5: =P5-Q5-R5 -> 1169.6935 | T5: =F5+D5 -> 29.7025 | U5: =D5*(1.02)*(0.25)+D5+F5 -> 34.7107 | V5: =D5*(1.02)*(0.5)+D5+F5 -> 39.7189 | W5: =$H5*T5 -> 772.265 | X5: =$H5*U5 -> 902.4782 | Y5: =$H5*V5 -> 1032.6914 | Z5: =$S5-W5 -> 397.4285 | AA5: =$S5-X5 -> 267.2153 | AB5: =$S5-Y5 -> 137.0021 | AC5: =Z5/$L5 -> 0.12044091 | AD5: =AA5/$L5 -> 0.080979732 | AE5: =AB5/$L5 -> 0.041518556 | AF5: =AS5/AG5 -> 0.057142857 | AG5: 35 | AH5: =W5/$L5 -> 0.2340353 | AI5: =X5/$L5 -> 0.27349648 | AJ5: =Y5/$L5 -> 0.31295765 | AS5: 2
B6: RH-ET042MW-FBA | C6: KD | D6: 19.64 | E6: =23*6*18/12/12/12 -> 1.4375 | F6: =E6*$F$3 -> 10.0625 | G6: 149.99 | H6: 26 | I6: =G6*H6 -> 3899.74 | J6: =$J$3 -> 0.15 | K6: =rounddown(H6*(1-J6),0) -> 22 | L6: =K6*G6 -> 3299.78 | M6: =L6*$M$3+3%*(H6-K6)*G6 -> 512.9658 | N6: 16.45 | O6: =N6*(H6) -> 427.7 | P6: =L6-M6-O6 -> 2359.1142 | Q6: =I6*$Q$3 -> 974.935 | R6: =I6*$R$3 -> 214.4857 | S6: =P6-Q6-R6 -> 1169.6935 | T6: =F6+D6 -> 29.7025 | U6: =D6*(1.02)*(0.25)+D6+F6 -> 34.7107 | V6: =D6*(1.02)*(0.5)+D6+F6 -> 39.7189 | W6: =$H6*T6 -> 772.265 | X6: =$H6*U6 -> 902.4782 | Y6: =$H6*V6 -> 1032.6914 | Z6: =$S6-W6 -> 397.4285 | AA6: =$S6-X6 -> 267.2153 | AB6: =$S6-Y6 -> 137.0021 | AC6: =Z6/$L6 -> 0.12044091 | AD6: =AA6/$L6 -> 0.080979732 | AE6: =AB6/$L6 -> 0.041518556 | AF6: =AS6/AG6 -> 0.081081081 | AG6: 37 | AH6: =W6/L6 -> 0.2340353 | AI6: =X6/$L6 -> 0.27349648 | AJ6: =Y6/$L6 -> 0.31295765 | AS6: 3
B7: RH-DR002MTMW-FBA | C7: Non-KD | D7: 17.26 | E7: =14.5*14.5*26.5/12/12/12 -> 3.22432 | F7: =E7*$F$3 -> 22.57024 | G7: 149.99 | H7: 21 | I7: =G7*H7 -> 3149.79 | J7: =$J$3 -> 0.15 | K7: =rounddown(H7*(1-J7),0) -> 17 | L7: =K7*G7 -> 2549.83 | M7: =L7*$M$3+3%*(H7-K7)*G7 -> 400.4733 | N7: 25.95 | O7: =N7*(H7) -> 544.95 | P7: =L7-M7-O7 -> 1604.4067 | Q7: =I7*$Q$3 -> 787.4475 | R7: =I7*$R$3 -> 173.23845 | S7: =P7-Q7-R7 -> 643.72075 | T7: =F7+D7 -> 39.83024 | U7: =D7*(1.02)*(0.25)+D7+F7 -> 44.23154 | V7: =D7*(1.02)*(0.5)+D7+F7 -> 48.63284 | W7: =$H7*T7 -> 836.43504 | X7: =$H7*U7 -> 928.86234 | Y7: =$H7*V7 -> 1021.2896 | Z7: =$S7-W7 -> -192.71429 | AA7: =$S7-X7 -> -285.14159 | AB7: =$S7-Y7 -> -377.56889 | AC7: =Z7/$L7 -> -0.075579271 | AD7: =AA7/$L7 -> -0.11182769 | AE7: =AB7/$L7 -> -0.1480761 | AF7: =AS7/AG7 -> 0.1369863 | AG7: 73 | AH7: =W7/L7 -> 0.32803561 | AI7: =X7/$L7 -> 0.36428403 | AJ7: =Y7/$L7 -> 0.40053244 | AS7: 10
B8: RH-DR001MW-FBA | C8: Non-KD | D8: 14.88 | E8: =14*14*26/12/12/12 -> 2.9490741 | F8: =E8*$F$3 -> 20.643519 | G8: 139.99 | H8: 16 | I8: =G8*H8 -> 2239.84 | J8: =$J$3 -> 0.15 | K8: =rounddown(H8*(1-J8),0) -> 13 | L8: =K8*G8 -> 1819.87 | M8: =L8*$M$3+3%*(H8-K8)*G8 -> 285.5796 | N8: 24.43 | O8: =N8*(H8) -> 390.88 | P8: =L8-M8-O8 -> 1143.4104 | Q8: =I8*$Q$3 -> 559.96 | R8: =I8*$R$3 -> 123.1912 | S8: =P8-Q8-R8 -> 460.2592 | T8: =F8+D8 -> 35.523519 | U8: =D8*(1.02)*(0.25)+D8+F8 -> 39.317919 | V8: =D8*(1.02)*(0.5)+D8+F8 -> 43.112319 | W8: =$H8*T8 -> 568.3763 | X8: =$H8*U8 -> 629.0867 | Y8: =$H8*V8 -> 689.7971 | Z8: =$S8-W8 -> -108.1171 | AA8: =$S8-X8 -> -168.8275 | AB8: =$S8-Y8 -> -229.5379 | AC8: =Z8/$L8 -> -0.059409241 | AD8: =AA8/$L8 -> -0.092768987 | AE8: =AB8/$L8 -> -0.12612873 | AF8: =AS8/AG8 -> 0.20512821 | AG8: 39 | AH8: =W8/L8 -> 0.31231698 | AI8: =X8/$L8 -> 0.34567672 | AJ8: =Y8/$L8 -> 0.37903647 | AS8: 8
B9: RH-ET003-N-FBA | C9: KD | D9: 51.79 | E9: =17.5*19.5*14.5/12/12/12 -> 2.8634983 | F9: =E9*$F$3 -> 20.044488 | G9: 199 | H9: 10 | I9: =G9*H9 -> 1990 | J9: =$J$3 -> 0.15 | K9: =rounddown(H9*(1-J9),0) -> 8 | L9: =K9*G9 -> 1592 | M9: =L9*$M$3+3%*(H9-K9)*G9 -> 250.74 | N9: 21.39 | O9: =N9*(H9) -> 213.9 | P9: =L9-M9-O9 -> 1127.36 | Q9: =I9*$Q$3 -> 497.5 | R9: =I9*$R$3 -> 109.45 | S9: =P9-Q9-R9 -> 520.41 | T9: =F9+D9 -> 71.834488 | U9: =D9*(1.02)*(0.25)+D9+F9 -> 85.040938 | V9: =D9*(1.02)*(0.5)+D9+F9 -> 98.247388 | W9: =$H9*T9 -> 718.34488 | X9: =$H9*U9 -> 850.40938 | Y9: =$H9*V9 -> 982.47388 | Z9: =$S9-W9 -> -197.93488 | AA9: =$S9-X9 -> -329.99938 | AB9: =$S9-Y9 -> -462.06388 | AC9: =Z9/$L9 -> -0.12433095 | AD9: =AA9/$L9 -> -0.20728604 | AE9: =AB9/$L9 -> -0.29024113 | AF9: =AS9/AG9 -> 0.30769231 | AG9: 39 | AH9: =W9/L9 -> 0.45122166 | AI9: =X9/$L9 -> 0.53417675 | AJ9: =Y9/$L9 -> 0.61713183 | AS9: 12
B10: RH-DR005MW-FBA | C10: KD | D10: 14.88 | E10: =14.5*15*6/12/12/12 -> 0.75520833 | F10: =E10*$F$3 -> 5.2864583 | G10: 99.99 | H10: 18 | I10: =G10*H10 -> 1799.82 | J10: =$J$3 -> 0.15 | K10: =rounddown(H10*(1-J10),0) -> 15 | L10: =K10*G10 -> 1499.85 | M10: =L10*$M$3+3%*(H10-K10)*G10 -> 233.9766 | N10: 11.71 | O10: =N10*(H10) -> 210.78 | P10: =L10-M10-O10 -> 1055.0934 | Q10: =I10*$Q$3 -> 449.955 | R10: =I10*$R$3 -> 98.9901 | S10: =P10-Q10-R10 -> 506.1483 | T10: =F10+D10 -> 20.166458 | U10: =D10*(1.02)*(0.25)+D10+F10 -> 23.960858 | V10: =D10*(1.02)*(0.5)+D10+F10 -> 27.755258 | W10: =$H10*T10 -> 362.99625 | X10: =$H10*U10 -> 431.29545 | Y10: =$H10*V10 -> 499.59465 | Z10: =$S10-W10 -> 143.15205 | AA10: =$S10-X10 -> 74.85285 | AB10: =$S10-Y10 -> 6.55365 | AC10: =Z10/$L10 -> 0.095444244 | AD10: =AA10/$L10 -> 0.049906891 | AE10: =AB10/$L10 -> 0.004369537 | AF10: =AS10/AG10 -> 0.10714286 | AG10: 56 | AH10: =W10/L10 -> 0.2420217 | AI10: =X10/$L10 -> 0.28755906 | AJ10: =Y10/$L10 -> 0.33309641 | AS10: 6
B11: Aggregate | I11: =sum(I5:I10) -> 16978.93 | L11: =sum(L5:L10) -> 14061.11 | M11: =sum(M5:M10) -> 2196.7011 | O11: =sum(O5:O10) -> 2215.91 | P11: =sum(P5:P10) -> 9648.4989 | Q11: =sum(Q5:Q10) -> 4244.7325 | R11: =sum(R5:R10) -> 933.84115 | S11: =sum(S5:S10) -> 4469.9253 | W11: =sum(W5:W10) -> 4030.6825 | X11: =sum(X5:X10) -> 4644.6103 | Y11: =sum(Y5:Y10) -> 5258.5381 | Z11: =sum(Z5:Z10) -> 439.24278 | AA11: =sum(AA5:AA10) -> -174.68502 | AB11: =sum(AB5:AB10) -> -788.61282 | AC11: =Z11/$L11 -> 0.03123813 | AD11: =AA11/$L11 -> -0.012423274 | AE11: =AB11/$L11 -> -0.056084677 | AF11: =AS11/AG11 -> 0.14695341 | AG11: =SUM(AG5:AG10) -> 279 | AH11: =W11/L11 -> 0.28665464 | AI11: =X11/$L11 -> 0.33031605 | AJ11: =Y11/$L11 -> 0.37397745 | AS11: =SUM(AS5:AS10) -> 41
S13: Discount on manufacturing cost | T13: 0.1
B15: SKU | T15: COGS 0% Tariff | U15: COGS 25% Tariff | V15: COGS 50% Tariff | W15: Gross COGS 0% Tariff | X15: Gross COGS 25% Tariff | Y15: Gross COGS 50% Tariff | Z15: Net Margin 0% Tariff | AA15: Net Margin 25% Tariff | AB15: Net Margin 50% Tariff | AC15: % Net Margin 0% Tariff | AD15: % Net margin 25% Tariff | AE15: % Net margin 50% Tariff
B16: RH-ET042MB(D)-FBA | T16: =F5+D5*(1-$T$13) -> 27.7385 | U16: =D5*(1.02)*(1.25)*(1-$T$13)+F5 -> 32.5994 | V16: =D5*(1.02)*(1.5)*(1-$T$13)+F5 -> 37.10678 | W16: =$H5*T16 -> 721.201 | X16: =$H5*U16 -> 847.5844 | Y16: =$H5*V16 -> 964.77628 | Z16: =$S5-W16 -> 448.4925 | AA16: =$S5-X16 -> 322.1091 | AB16: =$S5-Y16 -> 204.91722 | AC16: =Z16/$L5 -> 0.13591588 | AD16: =AA16/$L5 -> 0.097615326 | AE16: =AB16/$L5 -> 0.062100267
B17: RH-ET042MW-FBA | T17: =F6+D6*(1-$T$13) -> 27.7385 | U17: =D6*(1.02)*(1.25)*(1-$T$13)+F6 -> 32.5994 | V17: =D6*(1.02)*(1.5)*(1-$T$13)+F6 -> 37.10678 | W17: =$H6*T17 -> 721.201 | X17: =$H6*U17 -> 847.5844 | Y17: =$H6*V17 -> 964.77628 | Z17: =$S6-W17 -> 448.4925 | AA17: =$S6-X17 -> 322.1091 | AB17: =$S6-Y17 -> 204.91722 | AC17: =Z17/$L6 -> 0.13591588 | AD17: =AA17/$L6 -> 0.097615326 | AE17: =AB17/$L6 -> 0.062100267
B18: RH-DR002MTMW-FBA | T18: =F7+D7*(1-$T$13) -> 38.10424 | U18: =D7*(1.02)*(1.25)*(1-$T$13)+F7 -> 42.37609 | V18: =D7*(1.02)*(1.5)*(1-$T$13)+F7 -> 46.33726 | W18: =$H7*T18 -> 800.18904 | X18: =$H7*U18 -> 889.89789 | Y18: =$H7*V18 -> 973.08246 | Z18: =$S7-W18 -> -156.46829 | AA18: =$S7-X18 -> -246.17714 | AB18: =$S7-Y18 -> -329.36171 | AC18: =Z18/$L7 -> -0.061364206 | AD18: =AA18/$L7 -> -0.096546493 | AE18: =AB18/$L7 -> -0.12917007
B19: RH-DR001MW-FBA | T19: =F8+D8*(1-$T$13) -> 34.035519 | U19: =D8*(1.02)*(1.25)*(1-$T$13)+F8 -> 37.718319 | V19: =D8*(1.02)*(1.5)*(1-$T$13)+F8 -> 41.133279 | W19: =$H8*T19 -> 544.5683 | X19: =$H8*U19 -> 603.4931 | Y19: =$H8*V19 -> 658.13246 | Z19: =$S8-W19 -> -84.309096 | AA19: =$S8-X19 -> -143.2339 | AB19: =$S8-Y19 -> -197.87326 | AC19: =Z19/$L8 -> -0.046326988 | AD19: =AA19/$L8 -> -0.078705565 | AE19: =AB19/$L8 -> -0.10872934
B20: RH-ET003-N-FBA | T20: =F9+D9*(1-$T$13) -> 66.655488 | U20: =D9*(1.02)*(1.25)*(1-$T$13)+F9 -> 79.473513 | V20: =D9*(1.02)*(1.5)*(1-$T$13)+F9 -> 91.359318 | W20: =$H9*T20 -> 666.55488 | X20: =$H9*U20 -> 794.73513 | Y20: =$H9*V20 -> 913.59318 | Z20: =$S9-W20 -> -146.14488 | AA20: =$S9-X20 -> -274.32513 | AB20: =$S9-Y20 -> -393.18318 | AC20: =Z20/$L9 -> -0.091799547 | AD20: =AA20/$L9 -> -0.17231478 | AE20: =AB20/$L9 -> -0.24697436
B21: RH-DR005MW-FBA | T21: =F10+D10*(1-$T$13) -> 18.678458 | U21: =D10*(1.02)*(1.25)*(1-$T$13)+F10 -> 22.361258 | V21: =D10*(1.02)*(1.5)*(1-$T$13)+F10 -> 25.776218 | W21: =$H10*T21 -> 336.21225 | X21: =$H10*U21 -> 402.50265 | Y21: =$H10*V21 -> 463.97193 | Z21: =$S10-W21 -> 169.93605 | AA21: =$S10-X21 -> 103.64565 | AB21: =$S10-Y21 -> 42.17637 | AC21: =Z21/$L10 -> 0.11330203 | AD21: =AA21/$L10 -> 0.06910401 | AE21: =AB21/$L10 -> 0.028120392
B22: Aggregate | W22: =sum(W16:W21) -> 3789.9265 | X22: =sum(X16:X21) -> 4385.7976 | Y22: =sum(Y16:Y21) -> 4938.3326 | Z22: =sum(Z16:Z21) -> 679.99878 | AA22: =sum(AA16:AA21) -> 84.127682 | AB22: =sum(AB16:AB21) -> -468.40734 | AC22: =Z22/$L11 -> 0.048360249 | AD22: =AA22/$L11 -> 0.0059830043 | AE22: =AB22/$L11 -> -0.033312259
H24: 30 | I24: 79.99 | J24: =H24*I24 -> 2399.7 | T24: Line of action
H25: 2 | I25: 699.99 | J25: =H25*I25 -> 1399.98
H26: 4 | I26: 169.99 | J26: =H26*I26 -> 679.96 | T26: Jodhpur visit
H27: 32 | I27: 189.99 | J27: =H27*I27 -> 6079.68 | T27: - Jugaad billing to bypass tariffs
H28: 22 | I28: 419.99 | J28: =H28*I28 -> 9239.78 | T28: - Non-KD to KD
H29: 24 | I29: 379.99 | J29: =H29*I29 -> 9119.76 | T29: - KD mein 10% Factory price reduction
H30: 34 | I30: 309.99 | J30: =H30*I30 -> 10539.66 | T30: - Inventory sponshirship from Supplier - atleast 1 supplier
H31: 26 | I31: 249.99 | J31: =H31*I31 -> 6499.74
H32: 2 | I32: =249.99+199.99 -> 449.98 | J32: =H32*I32 -> 899.96 | T32: Full potential
H33: 2 | I33: =199.99+229.99 -> 429.98 | J33: =H33*I33 -> 859.96 | T33: - How much can these scale on Amazon
H34: 17 | I34: 279.99 | J34: =H34*I34 -> 4759.83 | T34: - Figure out how big this business can become
H35: 4 | I35: 649.99 | J35: =H35*I35 -> 2599.96 | T35: - Figure out how fast can this business grow
H36: 2 | I36: 449.99 | J36: =H36*I36 -> 899.98 | T36: - This business definition - Selling small KD furniture pieces on amazon which are priced atleast 20-30% higher than median price
H37: 29 | I37: 279.99 | J37: =H37*I37 -> 8119.71 | T37: - Consumer Survey to assess the demand for this business
H38: 7 | I38: 154.99 | J38: =H38*I38 -> 1084.93 | T38: - D2C - How big, How fast, GTM, Unit economics. What learnings can you derive from amazon for this? This question is more for future else there is a risk of getting restricted to becoming AZ seller
H39: 33 | I39: 139.99 | J39: =H39*I39 -> 4619.67
H40: 12 | I40: 139.99 | J40: =H40*I40 -> 1679.88 | T40: India Furniture market - Mayank conversation
H41: 19 | I41: 149.99 | J41: =H41*I41 -> 2849.81 | T41: - Define the business & market questions you want to talk about
H42: 28 | I42: 94.99 | J42: =H42*I42 -> 2659.72 | T42: - Understand his position - What does he wants to do?
H43: 33 | I43: 259.99 | J43: =H43*I43 -> 8579.67
H44: 44 | I44: 199.99 | J44: =H44*I44 -> 8799.56 | T44: New cross-border consumer angles
...

Sheet Amazon Unit Economics Model @15
F2: $7 per CFT | M2: 15% of net + 3% return admin on returned items | Q2: 25% of Gross sales | R2: 5% of Gross sales | W2: Net COGS in dollars calculated on gross sale units as returns will not be resold
F3: 7 | J3: 0.15 | M3: 0.15 | Q3: 0.25 | R3: 0.055
B4: SKU | C4: KD/Non-KD | D4: Factory cost | E4: CFT | F4: SEND Shipping | G4: ASP | H4: Gross Units | I4: Gross Sales | J4: Return % | K4: Net Units | L4: Net Sales | M4: AZ Selling Fees | N4: FBA Fulfilment Fees | O4: AZ Fulfillment fees | P4: OM1 | Q4: Ads | R4: Other costs | S4: Profit Before COGS | T4: Unit COGS 0% Tariff | U4: Unit COGS 15% Tariff | V4: Unit COGS 50% Tariff | W4: Gross COGS 0% Tariff | X4: Gross COGS 15% Tariff | Y4: Gross COGS 50% Tariff | Z4: Net Margin 0% Tariff | AA4: Net Margin 15% Tariff | AB4: Net Margin 50% Tariff | AC4: % Net Margin 0% Tariff | AD4: % Net margin 15% Tariff | AE4: % Net margin 50% Tariff | AF4: % returns | AG4: Gross sales (4 months) | AH4: Gross COGS % 0% Tariff | AI4: Gross COGS% 15% Tariff | AJ4: Gross COGS% 50% Tariff | AS4: Returns (4 months)
B5: RH-ET042MB(D)-FBA | C5: KD | D5: 19.64 | E5: =23*6*18/12/12/12 -> 1.4375 | F5: =E5*$F$3 -> 10.0625 | G5: 149.99 | H5: 26 | I5: =G5*H5 -> 3899.74 | J5: =$J$3 -> 0.15 | K5: =H5*(1-J5) -> 22.1 | L5: =K5*G5 -> 3314.779 | M5: =L5*$M$3+3%*(H5-K5)*G5 -> 514.76568 | N5: 16.45 | O5: =N5*(H5) -> 427.7 | P5: =L5-M5-O5 -> 2372.3133 | Q5: =I5*$Q$3 -> 974.935 | R5: =I5*$R$3 -> 214.4857 | S5: =P5-Q5-R5 -> 1182.8926 | T5: =F5+D5 -> 29.7025 | U5: =D5*(1.05)*(0.15)+D5+F5 -> 32.7958 | V5: =D5*(1.02)*(0.5)+D5+F5 -> 39.7189 | W5: =$H5*T5 -> 772.265 | X5: =$H5*U5 -> 852.6908 | Y5: =$H5*V5 -> 1032.6914 | Z5: =$S5-W5 -> 410.62762 | AA5: =$S5-X5 -> 330.20182 | AB5: =$S5-Y5 -> 150.20122 | AC5: =Z5/$L5 -> 0.12387783 | AD5: =AA5/$L5 -> 0.099615033 | AE5: =AB5/$L5 -> 0.045312589 | AF5: =AS5/AG5 -> 0.057142857 | AG5: 35 | AH5: =W5/$L5 -> 0.23297632 | AI5: =X5/$L5 -> 0.25723911 | AJ5: =Y5/$L5 -> 0.31154155 | AS5: 2
B6: RH-ET042MW-FBA | C6: KD | D6: 19.64 | E6: =23*6*18/12/12/12 -> 1.4375 | F6: =E6*$F$3 -> 10.0625 | G6: 149.99 | H6: 26 | I6: =G6*H6 -> 3899.74 | J6: =$J$3 -> 0.15 | K6: =H6*(1-J6) -> 22.1 | L6: =K6*G6 -> 3314.779 | M6: =L6*$M$3+3%*(H6-K6)*G6 -> 514.76568 | N6: 16.45 | O6: =N6*(H6) -> 427.7 | P6: =L6-M6-O6 -> 2372.3133 | Q6: =I6*$Q$3 -> 974.935 | R6: =I6*$R$3 -> 214.4857 | S6: =P6-Q6-R6 -> 1182.8926 | T6: =F6+D6 -> 29.7025 | U6: =D6*(1.05)*(0.15)+D6+F6 -> 32.7958 | V6: =D6*(1.02)*(0.5)+D6+F6 -> 39.7189 | W6: =$H6*T6 -> 772.265 | X6: =$H6*U6 -> 852.6908 | Y6: =$H6*V6 -> 1032.6914 | Z6: =$S6-W6 -> 410.62762 | AA6: =$S6-X6 -> 330.20182 | AB6: =$S6-Y6 -> 150.20122 | AC6: =Z6/$L6 -> 0.12387783 | AD6: =AA6/$L6 -> 0.099615033 | AE6: =AB6/$L6 -> 0.045312589 | AF6: =AS6/AG6 -> 0.081081081 | AG6: 37 | AH6: =W6/L6 -> 0.23297632 | AI6: =X6/$L6 -> 0.25723911 | AJ6: =Y6/$L6 -> 0.31154155 | AS6: 3
B7: RH-DR002MTMW-FBA | C7: Non-KD | D7: 17.26 | E7: =14.5*14.5*26.5/12/12/12 -> 3.22432 | F7: =E7*$F$3 -> 22.57024 | G7: 149.99 | H7: 21 | I7: =G7*H7 -> 3149.79 | J7: =$J$3 -> 0.15 | K7: =H7*(1-J7) -> 17.85 | L7: =K7*G7 -> 2677.3215 | M7: =L7*$M$3+3%*(H7-K7)*G7 -> 415.77228 | N7: 25.95 | O7: =N7*(H7) -> 544.95 | P7: =L7-M7-O7 -> 1716.5992 | Q7: =I7*$Q$3 -> 787.4475 | R7: =I7*$R$3 -> 173.23845 | S7: =P7-Q7-R7 -> 755.91327 | T7: =F7+D7 -> 39.83024 | U7: =D7*(1.05)*(0.15)+D7+F7 -> 42.54869 | V7: =D7*(1.02)*(0.5)+D7+F7 -> 48.63284 | W7: =$H7*T7 -> 836.43504 | X7: =$H7*U7 -> 893.52249 | Y7: =$H7*V7 -> 1021.2896 | Z7: =$S7-W7 -> -80.521773 | AA7: =$S7-X7 -> -137.60922 | AB7: =$S7-Y7 -> -265.37637 | AC7: =Z7/$L7 -> -0.030075496 | AD7: =AA7/$L7 -> -0.051398094 | AE7: =AB7/$L7 -> -0.099120099 | AF7: =AS7/AG7 -> 0.1369863 | AG7: 73 | AH7: =W7/L7 -> 0.31241487 | AI7: =X7/$L7 -> 0.33373747 | AJ7: =Y7/$L7 -> 0.38145947 | AS7: 10
B8: RH-DR001MW-FBA | C8: Non-KD | D8: 14.88 | E8: =14*14*26/12/12/12 -> 2.9490741 | F8: =E8*$F$3 -> 20.643519 | G8: 139.99 | H8: 16 | I8: =G8*H8 -> 2239.84 | J8: =$J$3 -> 0.15 | K8: =H8*(1-J8) -> 13.6 | L8: =K8*G8 -> 1903.864 | M8: =L8*$M$3+3%*(H8-K8)*G8 -> 295.65888 | N8: 24.43 | O8: =N8*(H8) -> 390.88 | P8: =L8-M8-O8 -> 1217.3251 | Q8: =I8*$Q$3 -> 559.96 | R8: =I8*$R$3 -> 123.1912 | S8: =P8-Q8-R8 -> 534.17392 | T8: =F8+D8 -> 35.523519 | U8: =D8*(1.05)*(0.15)+D8+F8 -> 37.867119 | V8: =D8*(1.02)*(0.5)+D8+F8 -> 43.112319 | W8: =$H8*T8 -> 568.3763 | X8: =$H8*U8 -> 605.8739 | Y8: =$H8*V8 -> 689.7971 | Z8: =$S8-W8 -> -34.202376 | AA8: =$S8-X8 -> -71.699976 | AB8: =$S8-Y8 -> -155.62318 | AC8: =Z8/$L8 -> -0.017964716 | AD8: =AA8/$L8 -> -0.037660241 | AE8: =AB8/$L8 -> -0.0817407 | AF8: =AS8/AG8 -> 0.20512821 | AG8: 39 | AH8: =W8/L8 -> 0.29853829 | AI8: =X8/$L8 -> 0.31823381 | AJ8: =Y8/$L8 -> 0.36231427 | AS8: 8
B9: RH-ET003-N-FBA | C9: KD | D9: 51.79 | E9: =17.5*19.5*14.5/12/12/12 -> 2.8634983 | F9: =E9*$F$3 -> 20.044488 | G9: 249.99 | H9: 10 | I9: =G9*H9 -> 2499.9 | J9: =$J$3 -> 0.15 | K9: =H9*(1-J9) -> 8.5 | L9: =K9*G9 -> 2124.915 | M9: =L9*$M$3+3%*(H9-K9)*G9 -> 329.9868 | N9: 21.39 | O9: =N9*(H9) -> 213.9 | P9: =L9-M9-O9 -> 1581.0282 | Q9: =I9*$Q$3 -> 624.975 | R9: =I9*$R$3 -> 137.4945 | S9: =P9-Q9-R9 -> 818.5587 | T9: =F9+D9 -> 71.834488 | U9: =D9*(1.05)*(0.15)+D9+F9 -> 79.991413 | V9: =D9*(1.02)*(0.5)+D9+F9 -> 98.247388 | W9: =$H9*T9 -> 718.34488 | X9: =$H9*U9 -> 799.91413 | Y9: =$H9*V9 -> 982.47388 | Z9: =$S9-W9 -> 100.21382 | AA9: =$S9-X9 -> 18.644572 | AB9: =$S9-Y9 -> -163.91518 | AC9: =Z9/$L9 -> 0.047161332 | AD9: =AA9/$L9 -> 0.008774267 | AE9: =AB9/$L9 -> -0.07713964 | AF9: =AS9/AG9 -> 0.30769231 | AG9: 39 | AH9: =W9/L9 -> 0.33805817 | AI9: =X9/$L9 -> 0.37644524 | AJ9: =Y9/$L9 -> 0.46235914 | AS9: 12
